Workbook
Name 年幼: 下拉列表!$W$93:$X$93
Name 特殊视野: 下拉列表!$W$94:$X$94
Name 感知: 下拉列表!$W$95:$X$95
Name 物法兼修: 下拉列表!$W$96
Name 长寿: 下拉列表!$W$97:$X$97
Name 复活: 下拉列表!$W$98:$X$98
Name 神民: 下拉列表!$W$99
Name 无需呼吸: 下拉列表!$W$100
Name 无需进食: 下拉列表!$W$101:$X$101
Name 无需睡眠: 下拉列表!$W$102
Name 元素耐受: 下拉列表!$W$103:$Z$103
Name 辅助机械: 下拉列表!$W$104:$X$104
Name 识别性知觉: 下拉列表!$W$105:$Y$105
Name 快速愈合: 下拉列表!$W$106:$X$106
Name 复苏: 下拉列表!$W$107
Name 悄无声息: 下拉列表!$W$108
Name 迷人: 下拉列表!$W$109
Name 感官强化: 下拉列表!$W$110:$Y$110
Name 迅捷步伐: 下拉列表!$W$111
Name 高速反应: 下拉列表!$W$112
Name 环境适应: 下拉列表!$W$113:$AA$113
Name 飞檐走壁: 下拉列表!$W$114
Name 平稳落地: 下拉列表!$W$115
Name 水性: 下拉列表!$W$116:$X$116
Name 毒液分泌: 下拉列表!$W$117:$Z$117
Name 体能充沛: 下拉列表!$W$118
Name 天然迷彩: 下拉列表!$W$119
Name 坚韧体魄: 下拉列表!$W$120
Name 硬肤: 下拉列表!$W$121
Name 装饰性器官: 下拉列表!$W$122:$Y$122
Name 固有武器: 下拉列表!$W$123:$Y$123
Name 第三只手: 下拉列表!$W$124
Name 耐寒: 下拉列表!$W$125
Name 感染者: 下拉列表!$W$126:$X$126
Name 年迈: 下拉列表!$W$127
Name 嗜睡: 下拉列表!$W$128:$X$128
Name 失眠: 下拉列表!$W$129
Name 易感: 下拉列表!$W$130
Name 迟钝: 下拉列表!$W$131
Name 感官障碍: 下拉列表!$W$132:$Y$132
Name 短寿: 下拉列表!$W$133
Name 化学依赖: 下拉列表!$W$134:$Y$134
Name 语言障碍: 下拉列表!$W$135:$X$135
Name 协调障碍: 下拉列表!$W$136
Name 弱不禁风: 下拉列表!$W$137
Name 元素脆弱: 下拉列表!$W$138
Name 自愈障碍: 下拉列表!$W$139:$X$139
Name 肢体缺失: 下拉列表!$W$140
Name 弱点: 下拉列表!$W$141
Name 独行长路: 下拉列表!$W$142:$X$142
Name 异格者: 下拉列表!$W$143:$X$143
Name 武器大师: 下拉列表!$W$144
Name 多重源石技艺: 下拉列表!$W$145:$Y$145
Name 飘忽不定: 下拉列表!$W$146
Name 追踪专家: 下拉列表!$W$147
Name 制造专家: 下拉列表!$W$148
Name 动物共情: 下拉列表!$W$149:$Y$149
Name 共情者: 下拉列表!$W$150
Name 猎杀者: 下拉列表!$W$151
Name 觉察者: 下拉列表!$W$152

Sheet 主卡
B2: 基础档案 | L2: 综合体检测试 | X2: 角色肖像 | AE2: 成长表 | AF2: 战斗 流派 | AG2: 成长 点数 | AH2: 教育成长次数 | AK2: 力量 | AL2: 源石技艺 | AM2: 战术 | AN2: 敏捷
B3: 【姓名】 | L3: 基础属性 | Q3: 总值 | S3: 基础 | T3: 修正 | U3: 成长 | AH3: 总数 | AI3: 成功 | AJ3: 失败
B4: 【玩家】 | L4: 生理耐受PR | Q4: =SUM(S4:U4) -> 5 | R4: < | S4: 5 | T4: =SUM(特质表!P3:特质表!P4) -> 0 | AG4: =AX9-SUM(AK4:AN4) -> 0 | AH4: =AX9-SUM(AI4:AJ4) -> 0 | AS4: =AX10 -> 1 | BC4: +
B5: 【性别】 | F5: 【年龄】 | L5: 反应机动MOB | Q5: =SUM(S5:U5) -> 5 | R5: < | S5: 5 | T5: =SUM(特质表!Q3:特质表!Q4) -> 0 | AF5: 非 战斗 流派 | AG5: 成长 点数 | AH5: 镇定 | AI5: 洞察 | AJ5: 情感 | AK5: 交涉 | AL5: 教育 | AM5: 技术 | AN5: 灵巧
B6: 【生日】 | L6: 物理强度PS | Q6: =SUM(S6:U6) -> 5 | R6: < | S6: 5 | T6: =SUM(特质表!R3:特质表!R4) -> 0 | AX6: 基础等级
B7: 【出身】 | L7: 精神意志SPR | Q7: =SUM(S7:U7) -> 5 | R7: < | S7: 5 | T7: =SUM(特质表!S3:特质表!S4) -> 0 | V7: 可分配属性点 | AG7: =AX9-SUM(AH7:AN7) -> 0
B8: 【种族】 | L8: 经验智慧INT | Q8: =SUM(S8:U8) -> 5 | R8: < | S8: 5 | T8: =SUM(特质表!T3:特质表!T4) -> 0 | AP8: =IFERROR(VLOOKUP(下拉列表!V2,下拉列表!V42:W44,2,0),"") -> =DISPIMG("ID_BA663A558C624BFBB40300DD5F36B5A5",1) | AV8: 基础等级 | AX8: 1
B9: 【职业】 | D9: 先锋 | F9: 【子职业】 | H9: 冲锋手 | L9: 源石技艺适应性OAA | Q9: =SUM(S9:U9) -> 5 | R9: < | S9: 5 | T9: =SUM(特质表!U3:特质表!U4) -> 0 | AE9: =VLOOKUP(D9,职业图标!A22:B29,2,0) -> =DISPIMG("ID_B4C652478C52453380C9AA09DFBAEA6F",1) | AG9: =IF(D9=0,"",D9) -> 先锋 | AR9: 精英化 | AV9: 升级次数
B10: 【身高】 | F10: 【体重】 | L10: 个人魅力APP | Q10: =SUM(S10:U10) -> 5 | R10: < | S10: 5 | T10: =SUM(特质表!V3:特质表!V4) -> 0 | V10: =INT((AX10-1)/5)-SUM(U4:U10) -> 0 | AK10: =IFERROR(VLOOKUP(D9,职业图标!J10:K17,2,FALSE),"") -> VANGUARD | AR10: ="阶段"&IF(AX10/5<=1,"零",IF(AX10/5<=2,"一","二")) -> 阶段零 | AV10: 当前等级 | AX10: =AX8+AX9 -> 1
A11: {=IFERROR(_xlfn.IFS(D10<SQRT(H10/24)*100,"偏胖",D10<SQRT(H10/18)*100,"均衡",D10>SQRT(H10/18),"偏瘦"),"")} | B11: 适宜身高 | D11: =ROUNDDOWN(SQRT(H10/24)*100,0)&"~"&ROUNDDOWN(SQRT(H10/18)*100,0)&"cm" -> 0~0cm | F11: 适宜体重 | H11: =下拉列表!V71&"~"&下拉列表!V70&"kg" -> 40~60kg | J11: {=IFERROR(_xlfn.IFS(H10>下拉列表!V70,"过重",H10<下拉列表!V70,"均衡",H10<下拉列表!V71,"过轻"),"")} -> 均衡 | P11: 总计 | Q11: =SUM(S11:U11) -> 35 | R11: = | S11: =SUM(S4:S10) -> 35 | T11: =SUM(T4:T10) -> 0 | U11: =SUM(U4:U10) -> 0
B12: 临床诊断分析 | L12: 主要特质
B13: 免疫力 | D13: 初始感染值 | F13: 感染值 | H13: 感染阶段 | L13: 种族 | R13: 文化 | X13: 工作 | AO13: 攻击范围 | AP13: =IFERROR(职业计算表!M3,"") -> =DISPIMG("ID_2FB619546A2944C291EBF3957FDE2776",1) | AV13: 武器适用 条件 | AW13: =IFERROR(职业计算表!O3,"") -> 伤害骰面为D6的近战物理武器 通常是各类长柄武器，如长枪和戟。 能够在中等距离发动灵活的突刺，将移动与伤害合为一体。
B14: =Q4 -> 5 | H14: =_xlfn.IFS(F14<20,"未感染",F14<40,"前期",F14<60,"中期",F14<80,"后期",F14<=100,"末期") -> 未感染 | AF14: =IFERROR(VLOOKUP(H9,职业图标!C22:D86,2,0),"") -> =DISPIMG("ID_411D84E06C08443995D759FB88AFFC25",1) | AI14: =IF(H9=0,"",H9) -> 冲锋手 | AL14: =_xlfn.DISPIMG("ID_A27648123EE64797A59A87ECD7AE0E88",1) -> =DISPIMG("ID_A27648123EE64797A59A87ECD7AE0E88",1)
B15: 固化症状 | F15: 临时发作 | G15: =IFERROR(VLOOKUP(C15,感染系统!$H$2:$I$17,2,0)," ") | L15: =IFERROR(VLOOKUP(L14,主要特质表!A2:D35,4,0),"") | R15: =IFERROR(VLOOKUP(R14,主要特质表!E2:H56,4,0),"") | X15: =IFERROR(VLOOKUP(X14,主要特质表!I2:L14,4,0),"")
G16: =IFERROR(VLOOKUP(C16,感染系统!$H$2:$I$17,2,0)," ")
G17: =IFERROR(VLOOKUP(C17,感染系统!$H$2:$I$17,2,0)," ")
G18: =IFERROR(VLOOKUP(C18,感染系统!$H$2:$I$17,2,0)," ") | AF18: 特性 | AO18: 可触发的被动 | AP18: 天赋清单：
B19: 长期疗程 | AF19: =IFERROR(职业计算表!N3,"") -> 穿戴中甲，具有中生命值 擅长通过快速移动对敌人造成大量伤害的近战输出职业 | AP19: SP 回复方式 | AR19: =IFERROR(职业计算表!S3,"") -> 你的回合结束时，如果你本回合主动移动过至少3个战术格，获得4SP。 每进入一个新的阶段，获得的SP+1
B22: 技能表 | AF22: 属性
AH23: 当前 | AI23: 上限 | AK23: 基础 | AL23: 成长 | AM23: 补正 | AP23: =战斗卡!H4 -> 0 | AR23: =战斗卡!H5 -> 0
E24: 总值 | F24: 成长 | G24: 修正 | H24: 加点 | L24: 总值 | M24: 成长 | N24: 修正 | O24: 加点 | S24: 总值 | T24: 成长 | U24: 修正 | V24: 加点 | Z24: 总值 | AA24: 成长 | AB24: 修正 | AC24: 加点 | AE24: =_xlfn.DISPIMG("ID_A1414AFFEBA04A01AEBDBA46D04A6C4F",1) -> =DISPIMG("ID_A1414AFFEBA04A01AEBDBA46D04A6C4F",1) | AF24: 生命值 | AI24: =IFERROR("/"&ROUNDDOWN(SUM(AK24:AM24),0),"") -> /15 | AJ24: < | AK24: =IFERROR(ROUNDDOWN(职业计算表!E2,0),"") -> 15 | AL24: =IFERROR(职业计算表!F2,"") -> 0 | AM24: =SUM(特质表!P9:P16) -> 0
B25: =_xlfn.DISPIMG("ID_FA5000DDCA5E4D81AB5A9A457C22EDDB",1) -> =DISPIMG("ID_FA5000DDCA5E4D81AB5A9A457C22EDDB",1) | C25: 物理强度 | F25: =Q6 -> 5 | I25: =_xlfn.DISPIMG("ID_131FF3363ED047DEB11CFC8572794CC4",1) -> =DISPIMG("ID_131FF3363ED047DEB11CFC8572794CC4",1) | J25: 经验智慧 | M25: =Q8 -> 5 | P25: =_xlfn.DISPIMG("ID_E9478C60C9034E3B8918B6E771168926",1) -> =DISPIMG("ID_E9478C60C9034E3B8918B6E771168926",1) | Q25: 反应机动 | T25: =Q5 -> 5 | W25: =_xlfn.DISPIMG("ID_9CEB13D933F741199F2CC7014B01EF49",1) -> =DISPIMG("ID_9CEB13D933F741199F2CC7014B01EF49",1) | X25: 源石技艺适应性 | AA25: =Q9 -> 5 | AE25: =_xlfn.DISPIMG("ID_D70E66E4768A4EA89893D4EFDCF2DD75",1) -> =DISPIMG("ID_D70E66E4768A4EA89893D4EFDCF2DD75",1) | AF25: 物理抗性 | AI25: =IFERROR("/"&ROUNDDOWN(SUM(AK25:AM25),0),"") -> /3 | AJ25: < | AK25: =IFERROR(职业计算表!K2,"") -> 3 | AL25: =IFERROR(AH46,"") | AM25: =SUM(特质表!Q9:Q16) -> 0 | AP25: =战斗卡!H8 -> 0 | AR25: =战斗卡!H9 -> 0
B26: ★ | C26: 力量 | E26: =SUM(F26:H26,下拉列表!V198)-SUM(H28:H33)&"/"&SUM(F26:H26,下拉列表!V198) -> 3/3 | F26: =AK4 -> 0 | G26: =SUM(特质表!P59:P66) -> 0 | J26: 战术 | L26: =SUM(M26:O26,下拉列表!V199)-SUM(O28:O30)&"/"&SUM(M26:O26,下拉列表!V199) -> 2/2 | M26: =AM4 -> 0 | N26: =SUM(特质表!P$125:P$155) -> 0 | Q26: 敏捷 | S26: =SUM(T26:V26,下拉列表!V200)-SUM(V28:V30)&"/"&SUM(T26:V26,下拉列表!V200) -> 2/2 | T26: =AN4 -> 0 | U26: =SUM(特质表!P$209:P$216) -> 0 | X26: 源石技艺理论 | Z26: =SUM(AA26:AC26,下拉列表!V201)-SUM(AC28:AC30)&"/"&SUM(AA26:AC26,下拉列表!V201) -> 2/2 | AA26: =AL4 -> 0 | AB26: =SUM(特质表!P$256:P$257) -> 0 | AE26: =_xlfn.DISPIMG("ID_19C3B78CC006403F8817388CB955E7F9",1) -> =DISPIMG("ID_19C3B78CC006403F8817388CB955E7F9",1) | AF26: 法术抗性 | AI26: =IFERROR("/"&ROUNDDOWN(SUM(AK26:AM26),0),"") -> /3 | AJ26: < | AK26: =IFERROR(职业计算表!M2,"") -> 3 | AL26: =IFERROR(AL46,"") | AM26: =SUM(特质表!R9:R16) -> 0
B27: ◎ | C27: 格斗 | E27: =SUM(F27:H27) -> 0 | F27: < | G27: =SUM(特质表!Q59:Q66) -> 0 | H27: =MAX(E28:E33) -> 0 | I27: ◎ | J27: 战术规划 | L27: =SUM(M27:O27) -> 0 | M27: < | N27: =SUM(特质表!Q$125:Q$155) -> 0 | O27: =MAX(L28:L30) -> 0 | P27: ◎ | Q27: 身法 | S27: =SUM(T27:V27) -> 0 | T27: < | U27: =SUM(特质表!Q$209:Q$216) -> 0 | V27: =MAX(S28:S30) -> 0 | W27: ◎ | X27: 施术 | Z27: =SUM(AB27:AC27) -> 0 | AA27: < | AB27: =SUM(特质表!Q$256:Q$257) -> 0 | AC27: =MAX(AC28:AC30) -> 0 | AE27: =_xlfn.DISPIMG("ID_EEDCD9ECDE6A4497A3362F50D354C631",1) -> =DISPIMG("ID_EEDCD9ECDE6A4497A3362F50D354C631",1) | AF27: 技力 | AH27: =IFERROR(职业计算表!Q2,"") -> 1.6666667 | AI27: =SUM(特质表!T9:T16) -> 0 | AJ27: =IFERROR(AH27+AI27,"") -> 1.6666667 | AK27: =下拉列表!V2*3+9 -> 9 | AL27: =SUM(特质表!S9:S16) -> 0 | AM27: =IFERROR(AL27+AK27,"") -> 9 | AP27: =战斗卡!H12 -> 0 | AR27: =战斗卡!H13 -> 0
C28: 长兵 | E28: =SUM(F28:H28) -> 0 | F28: < | G28: =SUM(特质表!R59:R66) -> 0 | J28: 支援技术 | L28: =SUM(M28:O28) -> 0 | M28: < | N28: =SUM(特质表!R$125:R$155) -> 0 | Q28: 短兵 | S28: =SUM(T28:V28) -> 0 | T28: < | U28: =SUM(特质表!R$209:R$216) -> 0 | Z28: =SUM(AB28:AC28) -> 0 | AA28: < | AB28: =SUM(特质表!R$256:R$257) -> 0 | AH28: 初动 | AI28: 补正 | AJ28: =_xlfn.DISPIMG("ID_5C660F1396F847E988890FB776B024D1",1) -> =DISPIMG("ID_5C660F1396F847E988890FB776B024D1",1) | AK28: 上限 | AL28: 补正 | AM28: =_xlfn.DISPIMG("ID_E00A0A014CCD414EA97973170AB8230F",1) -> =DISPIMG("ID_E00A0A014CCD414EA97973170AB8230F",1)
C29: 软兵 | E29: =SUM(F29:H29) -> 0 | F29: < | G29: =SUM(特质表!S59:S66) -> 0 | J29: 兵械操作 | L29: =SUM(M29:O29) -> 0 | M29: < | N29: =SUM(特质表!S$125:S$155) -> 0 | Q29: 暗器 | S29: =SUM(T29:V29) -> 0 | T29: < | U29: =SUM(特质表!S$209:S$216) -> 0 | Z29: =SUM(AB29:AC29) -> 0 | AA29: < | AB29: =SUM(特质表!S$256:S$257) -> 0 | AE29: 附加 数据 | AG29: 元素韧性 | AI29: =6+下拉列表!V2*3+AM29 -> 6 | AK29: 韧性修正 | AM29: 0 | AP29: =战斗卡!H16 -> 0 | AR29: =战斗卡!H17 -> 0
C30: 刀剑 | E30: =SUM(F30:H30) -> 0 | F30: < | G30: =SUM(特质表!T59:T66) -> 0 | J30: 生物驯养 | L30: =SUM(M30:O30) -> 0 | M30: < | N30: =SUM(特质表!T$125:T$155) -> 0 | Q30: 射击 | S30: =SUM(T30:V30) -> 0 | T30: < | U30: =SUM(特质表!T$209:T$216) -> 0 | Z30: =SUM(AB30:AC30) -> 0 | AA30: < | AB30: =SUM(特质表!T$256:T$257) -> 0 | AG30: 技艺点 | AI30: =IFERROR(VLOOKUP(AX10,下拉列表!V48:X66,3,0),"") -> 3 | AK30: 技艺点补正 | AM30: 0
C31: 拳术 | E31: =SUM(F31:H31) -> 0 | F31: < | G31: =SUM(特质表!U59:U66) -> 0 | J31: 教育 | L31: =SUM(M31:O31,M25)-SUM(O32:O37)&"/"&SUM(M31:O31,M25) -> 5/5 | M31: =AI4+IF(I31="※",AL7,0) -> 0 | N31: =SUM(特质表!P$159:P$166) -> 0 | Q31: 灵巧 | S31: =SUM(T31:V31,T25)-SUM(V32:V35)&"/"&SUM(T31:V31,T25) -> 5/5 | T31: =AN7+IF(P31="※",AX9,0) -> 0 | U31: =SUM(特质表!P$226:P$254) -> 0 | W31: 精神意志 | AA31: =Q7 -> 5 | AG31: 重量等级 | AI31: =IFERROR(简化卡!P25+AM31,"") -> 1 | AK31: 重量修正 | AM31: 0 | AP31: =战斗卡!AG16 -> 0 | AR31: =战斗卡!AG17 -> 0
C32: 钝器 | E32: =SUM(F32:H32) -> 0 | F32: < | G32: =SUM(特质表!V59:V66) -> 0 | J32: 理工学 | L32: =SUM(M32:O32) -> 0 | M32: < | N32: =SUM(特质表!Q$159:Q$166) -> 0 | Q32: 妙手 | S32: =SUM(T32:V32) -> 0 | T32: < | U32: =SUM(特质表!Q$226:Q$254) -> 0 | X32: 镇定 | Z32: =SUM(AA32:AC32,AA31)-SUM(AC33:AC35)&"/"&SUM(AA32:AC32,AA31) -> 5/5 | AA32: =AH7+IF(W32="※",AX9,0) -> 0 | AB32: =SUM(特质表!P$259:P$260) -> 0 | AG32: 耐力上限 | AI32: =ROUNDDOWN((Q9+Q6)/5,0)+AM32+INT((AX10-1)/5)*2 -> 2 | AK32: 耐力修正 | AM32: =SUM(特质表!U9:U16) -> 0
C33: 盾术 | E33: =SUM(F33:H33) -> 0 | F33: < | G33: =SUM(特质表!W59:W66) -> 0 | J33: 医药学 | L33: =SUM(M33:O33) -> 0 | M33: < | N33: =SUM(特质表!R$159:R$166) -> 0 | Q33: 急救 | S33: =SUM(T33:V33) -> 0 | T33: < | U33: =SUM(特质表!R$226:R$254) -> 0 | X33: 欺诈 | Z33: =SUM(AA33:AC33) -> 0 | AA33: < | AB33: =SUM(特质表!Q$259:Q$260) -> 0 | AE33: 武 器 | AF33: 武器名称 | AN33: 战斗相关 特质效果
B34: 个人魅力 | F34: =Q10 -> 5 | J34: 源石学 | L34: =SUM(M34:O34) -> 0 | M34: < | N34: =SUM(特质表!S$159:S$166) -> 0 | Q34: 驾驶 | S34: =SUM(T34:V34) -> 0 | T34: < | U34: =SUM(特质表!S$226:S$254) -> 0 | X34: 乔装 | Z34: =SUM(AA34:AC34) -> 0 | AA34: < | AB34: =SUM(特质表!R$259:R$260) -> 0 | AF34: 所属分支
B35: ※ | C35: 情感 | E35: =SUM(F35:H35,F34)-SUM(H36:H38)&"/"&SUM(F35:H35,F34) -> 5/5 | F35: =AJ7+IF(B35="※",AJ7,0) -> 0 | G35: =SUM(特质表!P75:P105) -> 0 | J35: 社会学 | L35: =SUM(M35:O35) -> 0 | M35: < | N35: =SUM(特质表!T$159:T$166) -> 0 | Q35: 舞蹈 | S35: =SUM(T35:V35) -> 0 | T35: < | U35: =SUM(特质表!T$226:T$254) -> 0 | X35: 潜行 | Z35: =SUM(AA35:AC35) -> 0 | AA35: < | AB35: =SUM(特质表!S$259:S$260) -> 0 | AF35: 防御技能 | AJ35: 武器骰面
C36: 声乐 | E36: =SUM(F36:H36) -> 0 | F36: < | G36: =SUM(特质表!Q75:Q105) -> 0 | J36: 政法学 | L36: =SUM(M36:O36) -> 0 | M36: < | N36: =SUM(特质表!U$159:U$166) -> 0 | P36: 额外附加技能 | X36: 洞察 | Z36: =SUM(AA36:AC36,AA31)-SUM(AC37:AC39)&"/"&SUM(AA36:AC36,AA31) -> 5/5 | AA36: =AI7+IF(W36="※",AX9,0) -> 0 | AB36: =SUM(特质表!P$262:P$263) -> 0 | AF36: 攻击类型 | AJ36: 伤害类型 | AN36: 武器配 件 | AO36: 名称
C37: 艺术 | E37: =SUM(F37:H37) -> 0 | F37: < | G37: =SUM(特质表!R75:R105) -> 0 | J37: 经管学 | L37: =SUM(M37:O37) -> 0 | M37: < | N37: =SUM(特质表!V$159:V$166) -> 0 | P37: 附加技能A | S37: =SUM(T37:V37) -> 0 | T37: < | X37: 调查 | Z37: =SUM(AA37:AC37) -> 0 | AA37: < | AB37: =SUM(特质表!Q$262:Q$263) -> 0 | AF37: 依赖属性 | AJ37: 属性值 | AL37: =IFERROR(VLOOKUP(AH37,简化卡!C2:D8,2,0),"") | AO37: 效 果 | AP37: =IFERROR(VLOOKUP(AP36,配件及消耗品!$A$2:$C$38,3,0),"") | AT37: =IFERROR(VLOOKUP(AT36,配件及消耗品!$A$2:$C$38,3,0),"") | AX37: =IFERROR(VLOOKUP(AX36,配件及消耗品!$A$2:$C$38,3,0),"")
C38: 心理 | E38: =SUM(F38:H38) -> 0 | F38: < | G38: =SUM(特质表!S75:S105) -> 0 | J38: 技术 | L38: =SUM(M38:O38,M25)-SUM(O39:O42)&"/"&SUM(M38:O38,M25) -> 5/5 | M38: =AM7+IF(I38="※",AX9,0) -> 0 | N38: =SUM(特质表!P$175:P$205) -> 0 | P38: 附加技能B | S38: =SUM(T38:V38) -> 0 | T38: < | X38: 觉察 | Z38: =SUM(AA38:AC38) -> 0 | AA38: < | AB38: =SUM(特质表!R$262:R$263) -> 0 | AF38: 攻击技能 | AJ38: 技能值 | AL38: =IFERROR(VLOOKUP(AH38,简化卡!J2:K21,2,0),"")
C39: 交涉 | E39: =SUM(F39:H39,F34)-SUM(H40:H42)&"/"&SUM(F39:H39,F34) -> 5/5 | F39: =AK7+IF(B39="※",AJ7,0) -> 0 | G39: =SUM(特质表!P109:P116) -> 0 | J39: 农林渔牧 | L39: =SUM(M39:O39) -> 0 | M39: < | N39: =SUM(特质表!Q$175:Q$205) -> 0 | P39: 附加技能C | S39: =SUM(T39:V39) -> 0 | T39: < | X39: 追踪 | Z39: =SUM(AA39:AC39) -> 0 | AA39: < | AB39: =SUM(特质表!S$262:S$263) -> 0 | AF39: 效能骰 | AH39: =IFERROR(AL38&"D"&AL35&"+"&AL37,"") -> D+ | AJ39: 效能期望 | AL39: =IFERROR("["&(AL35+1)*AL38/2+AL37&"]="&ROUNDDOWN((AL35+1)*AL38/2+AL37,0),"")
C40: 游说 | E40: =SUM(F40:H40) -> 0 | F40: < | G40: =SUM(特质表!Q109:Q116) -> 0 | J40: 手工工艺 | L40: =SUM(M40:O40) -> 0 | M40: < | N40: =SUM(特质表!R$175:R$205) -> 0 | P40: 附加技能D | S40: =SUM(T40:V40) -> 0 | T40: < | W40: 附加技能 | AF40: 辅助骰 | AH40: =IFERROR(AL38&"D2","") -> D2 | AJ40: 辅助期望 | AL40: =IFERROR("["&3*AL38/2&"]="&ROUNDDOWN(3*AL38/2,0),"") | AO40: 名称
C41: 取悦 | E41: =SUM(F41:H41) -> 0 | F41: < | G41: =SUM(特质表!R109:R116) -> 0 | J41: 机械工程 | L41: =SUM(M41:O41) -> 0 | M41: < | N41: =SUM(特质表!S$175:S$205) -> 0 | P41: 附加技能E | S41: =SUM(T41:V41) -> 0 | T41: < | X41: 先史 | Z41: =SUM(AA41:AC41) -> 0 | AA41: < | AF41: 武器 描述 | AO41: 效 果 | AP41: =IFERROR(VLOOKUP(AP40,配件及消耗品!$A$2:$C$38,3,0),"") | AT41: =IFERROR(VLOOKUP(AT40,配件及消耗品!$A$2:$C$38,3,0),"") | AX41: =IFERROR(VLOOKUP(AX40,配件及消耗品!$A$2:$C$38,3,0),"")
C42: 威吓 | E42: =SUM(F42:H42) -> 0 | F42: < | G42: =SUM(特质表!S109:S116) -> 0 | J42: 电子工程 | L42: =SUM(M42:O42) -> 0 | M42: < | N42: =SUM(特质表!T$175:T$205) -> 0 | P42: 附加技能F | S42: =SUM(T42:V42) -> 0 | T42: < | X42: 通用语 | Z42: =SUM(AA42:AC42) -> 5 | AA42: < | AB42: =Q8 -> 5
B44: 信 誉 系 统 | AE44: 防 具 | AF44: 防具名称 | AN44: 防具配 件 | AO44: 名称
...

Sheet 特质表
B1: 如果特质槽位不足，可以通过点击最左侧+号按钮来展开额外修正因子和特质列表！ 点击左上角123按钮可以快速切换展开/折叠 | F1: 感谢 阿云(QQ@3588635784)对特质表的自动化 以及其他优化工作！ | O1: （仅提供主要特质的自动修正） 感谢@星辰晚冬 的协助编写
B2: 我的特质 | C2: 特质名称 | E2: 特质描述 | F2: 特质效果 | G2: 点数花费 | H2: 总花费 | I2: =SUM(I3,I103,I253)-SUM(I53,I153) -> 0 | J2: 基础点数 | K2: 40 | L2: 对于自定义特质的数值估算： 1基础属性=10特质点 2非战斗副属性=5特质点 1非战斗技能=5特质点 1战斗副属性=10特质点 1战斗技能值=20特质点 1经济评级=1特质点=1社交点 | O2: 基础属性 | P2: 生理耐受 | Q2: 反应机动 | R2: 物理强度 | S2: 精神意志 | T2: 经验智慧 | U2: 源石技艺适应性 | V2: 个人魅力
B3: 躯体 天赋 | H3: 总花费 | I3: =SUM(G3:G32) -> 0 | J3: 成长 | K3: =INT((主卡!AX10-1)/5)*25 -> 0 | O3: 手动修正
C4: 修正因子 | J4: 来自主要 | K4: =-SUM(主要特质表!B37,主要特质表!F57,主要特质表!J16) -> 0 | O4: 自动修正 | P4: {=SUM(参数!B2:B105*参数!C2:C105)} -> 0 | Q4: {=SUM(参数!B2:B105*参数!D2:D105)} -> 0 | R4: {=SUM(参数!B2:B105*参数!E2:E105)} -> 0 | S4: {=SUM(参数!B2:B105*参数!F2:F105)} -> 0 | T4: {=SUM(参数!B2:B105*参数!G2:G105)} -> 0 | U4: {=SUM(参数!B2:B105*参数!H2:H105)} -> 0 | V4: {=SUM(参数!B2:B105*参数!I2:I105)} -> 0
C5: 修正因子
C6: 修正因子 | O6: 杂项属性 | P6: 生命值 | Q6: 物理抗性 | R6: 法术抗性 | S6: SP上限 | T6: 初动 | U6: 耐力上限
C7: 修正因子
C9: 修正因子 | J9: 特质表花费 | K9: =I3+I103 -> 0 | O9: 手动修正
C10: 修正因子
C11: 修正因子
C12: 修正因子
J13: 总返还 | K13: =I53+I153 -> 0 | O13: 自动修正
C14: 修正因子
C15: 修正因子
C16: 修正因子
C17: 修正因子 | J17: 剩余点数 | K17: =K2+K3+K4-SUM(I3:I182,I253) -> 40 | O17: 战斗属性
C19: 修正因子
C20: 修正因子
C21: 修正因子
C22: 修正因子
C24: 修正因子
C25: 修正因子 | O25: 手动修正
C26: 修正因子
C27: 修正因子
C29: 修正因子
C30: 修正因子
C31: 修正因子
C32: 修正因子
C34: 修正因子
C35: 修正因子
C36: 修正因子
C37: 修正因子
C39: 修正因子
C40: 修正因子
... C52: 修正因子
B53: 躯体 缺陷 | H53: 总返还 | I53: =SUM(G53:G82) -> 0 | J53: 特殊效果总结
C54: 修正因子 | O54: 自动修正
C55: 修正因子
C56: 修正因子 | O56: 力量流派 | P56: 力量 | Q56: 格斗 | R56: 长兵 | S56: 软兵 | T56: 刀剑 | U56: 拳术 | V56: 钝器 | W56: 盾术
C57: 修正因子
...

Sheet 战斗卡
A1: =主卡!AE9 -> =DISPIMG("ID_B4C652478C52453380C9AA09DFBAEA6F",1) | B1: =主卡!AG9 -> 先锋 | D1: =主卡!AK10 -> VANGUARD | AF1: 撰写人：小半
F3: 精英化阶段零 | G3: 精零天赋 | AF3: 精英化零阶段 被动技艺
A4: =主卡!AF14 -> =DISPIMG("ID_411D84E06C08443995D759FB88AFFC25",1) | C4: =主卡!AI14 -> 冲锋手 | G4: 天赋名称 | L4: 行动消耗 | M4: 0 | N4: 0 | O4: 释放范围 | Q4: 行动消耗 | R4: 0 | S4: 0 | T4: 释放范围 | V4: 行动消耗 | W4: 0 | X4: 0 | Y4: 释放范围 | AA4: 行动消耗 | AB4: 0 | AC4: 0 | AD4: 释放范围 | AF4: 技艺名称
G5: 天赋效果 | L5: 资源消耗 | M5: 0 | N5: 0 | O5: 生效目标 | Q5: 资源消耗 | R5: 0 | S5: 0 | T5: 生效目标 | V5: 资源消耗 | W5: 0 | X5: 0 | Y5: 生效目标 | AA5: 资源消耗 | AB5: 0 | AC5: 0 | AD5: 生效目标 | AF5: 被动技艺效果
A6: 分支 特性 | B6: =主卡!AF19 -> 穿戴中甲，具有中生命值 擅长通过快速移动对敌人造成大量伤害的近战输出职业 | L6: 技艺效果 | Q6: 技艺效果 | V6: 技艺效果 | AA6: 技艺效果
A7: 武器 类型 | B7: =主卡!AW13 -> 伤害骰面为D6的近战物理武器 通常是各类长柄武器，如长枪和戟。 能够在中等距离发动灵活的突刺，将移动与伤害合为一体。 | F7: 精英化阶段一 | G7: 精一天赋 | AF7: 精英化一阶段 被动技艺
G8: 天赋名称 | L8: 行动消耗 | M8: 0 | N8: 0 | O8: 释放范围 | Q8: 行动消耗 | R8: 0 | S8: 0 | T8: 释放范围 | V8: 行动消耗 | W8: 0 | X8: 0 | Y8: 释放范围 | AA8: 行动消耗 | AB8: 0 | AC8: 0 | AD8: 释放范围 | AF8: 技艺名称
G9: 天赋效果 | L9: 资源消耗 | M9: 0 | N9: 0 | O9: 生效目标 | Q9: 资源消耗 | R9: 0 | S9: 0 | T9: 生效目标 | V9: 资源消耗 | W9: 0 | X9: 0 | Y9: 生效目标 | AA9: 资源消耗 | AB9: 0 | AC9: 0 | AD9: 生效目标 | AF9: 被动技艺效果
A10: SP 回复 | B10: =主卡!AR19 -> 你的回合结束时，如果你本回合主动移动过至少3个战术格，获得4SP。 每进入一个新的阶段，获得的SP+1 | L10: 技艺效果 | Q10: 技艺效果 | V10: 技艺效果 | AA10: 技艺效果
F11: 精英化阶段二 | G11: 精二天赋 | AF11: 精英化二阶段 被动技艺
A12: 攻 击 范 围 | B12: =主卡!AP13 -> =DISPIMG("ID_2FB619546A2944C291EBF3957FDE2776",1) | G12: 天赋名称 | L12: 行动消耗 | M12: 0 | N12: 0 | O12: 释放范围 | Q12: 行动消耗 | R12: 0 | S12: 0 | T12: 释放范围 | V12: 行动消耗 | W12: 0 | X12: 0 | Y12: 释放范围 | AA12: 行动消耗 | AB12: 0 | AC12: 0 | AD12: 释放范围 | AF12: 技艺名称
G13: 天赋效果 | L13: 资源消耗 | M13: 0 | N13: 0 | O13: 生效目标 | Q13: 资源消耗 | R13: 0 | S13: 0 | T13: 生效目标 | V13: 资源消耗 | W13: 0 | X13: 0 | Y13: 生效目标 | AA13: 资源消耗 | AB13: 0 | AC13: 0 | AD13: 生效目标 | AF13: 被动技艺效果
L14: 技艺效果 | Q14: 技艺效果 | V14: 技艺效果 | AA14: 技艺效果
F15: 模组阶段 | G15: 模组阶段 被动技艺 | AF15: 模组阶段 被动技艺
A16: 生命值 上限 | B16: =IFERROR(ROUNDDOWN(SUM(主卡!AK24:AM24),0),"") -> 15 | G16: 天赋名称 | L16: 行动消耗 | M16: 0 | N16: 0 | O16: 释放范围 | Q16: 行动消耗 | R16: 0 | S16: 0 | T16: 释放范围 | V16: 行动消耗 | W16: 0 | X16: 0 | Y16: 释放范围 | AA16: 行动消耗 | AB16: 0 | AC16: 0 | AD16: 释放范围 | AF16: 天赋名称
A17: 法术 抗性 | B17: =IFERROR(ROUNDDOWN(SUM(主卡!AK25:AM25),0),"") -> 3 | G17: 天赋效果 | L17: 资源消耗 | M17: 0 | N17: 0 | O17: 生效目标 | Q17: 资源消耗 | R17: 0 | S17: 0 | T17: 生效目标 | V17: 资源消耗 | W17: 0 | X17: 0 | Y17: 生效目标 | AA17: 资源消耗 | AB17: 0 | AC17: 0 | AD17: 生效目标 | AF17: 天赋效果
A18: 物理 抗性 | B18: =IFERROR(ROUNDDOWN(SUM(主卡!AK26:AM26),0),"") -> 3 | L18: 技艺效果 | Q18: 技艺效果 | V18: 技艺效果 | AA18: 技艺效果

Sheet 战斗信息速查表
A1: 主动动作 | B1: 消耗 | C1: 条件 | D1: 效果 | E1: 正面状态 | F1: 状态效果 | G1: 负面状态 | H1: 状态效果 | I1: 生效范围
A2: 普通攻击 | B2: 1主要行动 | C2: 持有武器 | D2: 使用武器对目标进行一次普通攻击。 | E2: 伤害强化X | F2: 攻击的最终伤害+X。 | G2: 脆弱X | H2: 受到的伤害+X | I2: 范围图例 | J2: 描述1 | K2: 范围图例 | L2: 描述
A3: 轻击 | B3: 1主要行动 | C3: 持有武器 | D3: 使用武器对目标进行一次普通攻击，但不造成伤害。 | E3: 精准 | F3: 无视目标的动作：【完全闪避】。 | G3: 失能 | H3: 无法执行任何动作。 | I3: =_xlfn.DISPIMG("ID_F24032A0ABB24BAD95DE4231078C89A4",1) -> =DISPIMG("ID_F24032A0ABB24BAD95DE4231078C89A4",1) | J3: 阶梯1 中心4 “轰隆隆先生” | K3: =_xlfn.DISPIMG("ID_316C90CB662848898D225F2BA6B737CC",1) -> =DISPIMG("ID_316C90CB662848898D225F2BA6B737CC",1) | L3: 距离1 中心8 “剑雨滂沱”
A4: 警戒 | B4: 1主要行动 | C4: 有角色移动，且移动前位于角色的武器攻击范围内 | D4: 立即在该角色移动前对其进行一次普通攻击。同次警戒内，对每个单位仅触发一次。 | E4: 魅影 | F4: 进行动作：【完全闪避】时，不再消耗行动。 | G4: 标记 | H4: 无效果，但同时被视为【停顿】，【震颤】，【寒冷】，【困顿】。
A5: 瞄准 | B5: 1主要行动 | C5: 视野内 | D5: 施加“被瞄准”。“被瞄准”：施加者可指定该单位作为远程攻击的目标，在该单位离开施加者的视野，或进入掩体；施加者受到攻击，主动更换目标或移动后解除。 | E5: 嘲讽 | F5: 被嘲讽的角色应当攻击的目标，没有实际意义。 | G5: 寒冷 | H5: 无法获取快速行动。当拥有“寒冷”时再次被施加“寒冷”，升级为“冻结”。
E6: 被嘲讽 | F6: 攻击没有【嘲讽】的目标时，造成的折后伤害降低50% | G6: 冻结 | H6: 失能，物理抗性+10，法术抗性-10。回合结束一次后，解除本效果。 | I6: =_xlfn.DISPIMG("ID_9E0615141E544072985A467390B07B49",1) -> =DISPIMG("ID_9E0615141E544072985A467390B07B49",1) | J6: 阶梯2 中心12 “剑雨” | K6: =_xlfn.DISPIMG("ID_256465A6DA5D45AAA99BC6A000B2D0A1",1) -> =DISPIMG("ID_256465A6DA5D45AAA99BC6A000B2D0A1",1) | L6: 距离2 中心20 “药物配置”
A7: 投掷物品 | B7: 1快速行动 | C7: 携带了对应的投掷物 | D7: 选择一个攻击范围内的战术格，基于该战术格触发投掷物所具有的对应效果。 | E7: 迅捷 | F7: 下一轮最先行动。多个角色存在迅捷时，按常规先攻规则排位。 | G7: 麻痹 | H7: 无法获取主要行动。当拥有“麻痹”时再次被施加“麻痹”，升级为“眩晕”。
A8: 切换武器 | B8: 无消耗 | C8: 拥有多把武器 | D8: 改变自己所持有的武器。包括武器的变形，弹药种类的切换，以及交换背包中和自己所持有的武器。 | E8: 护盾X | F8: 抵消受到的攻击，生效后X-1，X为0时终止该状态。 | G8: 眩晕 | H8: 失能。
A9: 移动预备 | B9: 1快速行动 | C9: 无 | D9: 获得3个移动位 | E9: 屏障X | F9: 获得X点临时HP，X为0时终止该状态。 | G9: 停顿 | H9: 通过【移动预备】获得的移动位固定为1；被重复施加“停顿”时升级为“束缚”。 | I9: =_xlfn.DISPIMG("ID_65FCD58497EF437FA699165EA403C4BB",1) -> =DISPIMG("ID_65FCD58497EF437FA699165EA403C4BB",1) | J9: 阶梯3 中心24 “火山” | K9: =_xlfn.DISPIMG("ID_B4EB322AA68242E1B2447C8B8A70DCEA",1) -> =DISPIMG("ID_B4EB322AA68242E1B2447C8B8A70DCEA",1) | L9: 距离3 中心36 “（暂无）”
A10: 跳跃 | B10: 1快速行动 | C10: 有中心20范围内的一个高度不高于自身的战术格为目标格 | D10: 进行一次难度基于环境复杂度的身法检定，若成功，则向目标格位移且无视移动路径中的地形效果，若这一动作使自身受到摔落伤害，将伤害值减半；若失败，则由SN决定发生了什么（不好的事） | E10: 隐匿 | F10: 只能在合适的环境下（如黑暗处）生效。在其他人眼中不可见，不可被其他人选取为目标。 | G10: 束缚 | H10: 无法获得移动位，不可进行主动移动。
A11: 攀援 | B11: 1快速行动 | C11: 有中心8范围内的一个高台战术格为目标格 | D11: 进行一次难度基于环境复杂度的身法检定，若成功，则向目标格位移；若失败，则由SN决定发生了什么（不好的事）。 | E11: 迷彩 | F11: 在任何环境下都可生效，在其他人眼中不可见，不可被其他人选取为目标。 | G11: 困顿 | H11: 无法执行反应动作。当拥有“困顿”时再次被施加“困顿”，升级为“睡眠”。
A12: 移动 | B12: 1移动位 | C12: 有九宫格范围内的一个可通行战术格为目标格 | D12: 向目标格位移。特别地，若选择了一个斜向战术格为目标格，本回合内第二次（或是之后的偶数次）选择相同方向的战术格为目标格时消耗的移动位+1 | E12: 抵抗 | F12: 无效被施加的状态，由被施加者选择是否生效。 | G12: 睡眠 | H12: 失能，状态解除时，失去快速行动。HP因受到攻击而减少后，解除本效果。
E13: 元素屏障X | F13: 获得X点临时元素韧性。 | G13: 失重 | H13: 重量降低X；若重量因此低于0，获得浮空。
A14: 转向 | B14: 无消耗 | C14: 进行了移动预备，或执行了某个消耗了主要行动的动作的之前或之后，尚未进行另一个新的动作时 | D14: 改变自己的朝向，进而改变自己的攻击范围。 | E14: 暴击 | F14: 攻击时，全部造成伤害的骰子的投掷结果被固定为最大值。 | G14: 浮空 | H14: 所在高度层+1，失能，重量变为0。
A15: 潜行 | B15: 1主要行动 | C15: 环境允许 | D15: 进行一次潜行检定，获得状态“隐匿” | E15: 免疫 | F15: 不受任何外界效果影响。 | G15: 沉默 | H15: 无法释放技艺
A16: 侦测 | B16: 1快速行动 | C16: 无 | D16: 进行一次检定难度基于环境复杂度的【觉察】或【调查】检定，若成功，移除在你视野范围内的所有单位的“隐匿”与“迷彩”。 | E16: 穿透 | F16: 攻击无视掩体效果。 | G16: 战栗 | H16: 无法进行动作：【攻击】
A17: 急救 | B17: 1主要行动 | C17: 面前战术格范围内存在角色 | D17: 进入引导直至自身的下一次回合开始，使对方的生命值恢复等同于其最大生命值×20% | E17: 亲和 | F17: 受到治疗时，治疗来源的效能骰获得骰面升级。 | G17: 禁疗 | H17: 受到的生命值恢复效果失效。
A18: 反应动作 | B18: 消耗 | C18: 条件 | D18: 效果 | E18: 加重X | F18: 重量等级增加X | G18: 迟缓 | H18: 将你在下一轮次的回合置于该轮次的末尾，与“迅捷”相抵消。生效一次后，结束状态。
A19: 完全闪避 | B19: 1主要行动 | C19: 受到攻击 | D19: 使用一个身法检定与攻击方的伤害对抗；若对抗成功，则抵消本次攻击。 | E19: 特殊状态 | F19: 状态效果 | G19: 流血 | H19: 每主动移动一次，失去当前10%的HP。
A20: 完全格挡/招架 | B20: 1主要行动 | C20: 受到攻击 | D20: 使用一个格斗检定与攻击方的伤害对抗；若对抗成功，则抵消本次攻击。 | E20: 飞行 | F20: 在自己的每个回合内，可以改变自己的所处高度一层而不受地形限制。 | G20: 恐惧 | H20: 当周围8格没有友方单位，仅能执行【移动预备】与【移动】
A21: 阻挡打击 | B21: 无消耗 | C21: 一个单位以与自身朝向不同的方向离开自身的控制区。借机攻击同时满足条件时，可同时触发 | D21: 对该角色进行一次普通攻击，攻击命中后，对其施加“束缚”，持续至该目标回合结束一次。 | E21: 引导 | F21: 进行任意动作时，将该状态来源的技艺终止，并结束此状态。 | G21: 目盲 | H21: 无法选中除自己以外的目标。
A22: 重振 | B22: 1耐力 | C22: 自身处于“濒死”，且受到了生命值回复效果时 | D22: 清除“濒死”，并使自身的生命值改为等同于本次生命值回复值。 | E22: 失衡 | F22: 当单位以并非来源于自身的效果而被迫移动期间，视为具有该状态。 | G22: 地块名称 | H22: 地块效果
E23: 损伤名称 | F23: 效果 | G23: 高台 | H23: 位于该地块的单位，无法被地面单位的行动：【近战攻击】指定
E24: 凋亡损伤爆发 | F24: 立即造成两次等同于损伤施加者辅助骰的真实伤害，并施加【迟缓】。失去3SP，若没有SP可以失去，改为额外造成一次等同于损伤施加者辅助骰的真实伤害。 | G24: 陷坑 | H24: 位于该地块的单位，视作濒死并离开战场
F25: 元素损伤爆发期持续至该角色的回合开始1次。 | G25: 草丛 | H25: 位于该地块内的单位，获得【隐匿】
E26: 组织损伤 | F26: 立即造成三次等同于损伤施加者辅助骰的真实伤害，并施加【迟缓】。
F27: 元素损伤爆发期持续至该角色的回合开始1次。 | G27: 热泵通道 | H27: 在每轮次开始时，对位于该地块的单位造成5灼燃损伤
E28: 毒性损伤爆发 | F28: 立即造成两次等同于损伤施加者辅助骰的真实伤害，并施加【迟缓】。 | G28: 活性源石 | H28: 当任意单位经过此地块时，获得【力量10】【涌动10】，但每轮次开始时，感染值/恶化值+2
F29: 元素损伤爆发期间，【禁疗】，持续至该角色回合开始1次。 | G29: 腐蚀地面 | H29: 位于该地块的单位，物理抗性减半
E30: 侵蚀损伤爆发 | F30: 立即造成两次等同于损伤施加者辅助骰的真实伤害，并施加【迟缓】。 | G30: 岩浆喷射处 | H30: 在每回合开始时，对周围8格单位造成3灼燃损伤
F31: 元素损伤爆发期间，受到的物理伤害增加一个来自攻击者的辅助骰，持续至该角色回合开始1次。 | G31: 沼泽 | H31: 经过此地块消耗的移动位翻倍
E32: 灼燃损伤爆发 | F32: 立即造成两次等同于损伤施加者辅助骰的真实伤害，并施加【迟缓】。 | G32: 冰面 | H32: 位于该地块的单位，重量-1
F33: 元素损伤爆发期间，受到的法术伤害增加一个来自攻击者的辅助骰，持续至该角色回合开始1次。 | G33: 深水区 | H33: 每轮次开始时，对位于该地块的单位造成5侵蚀损伤
E34: 神经损伤爆发 | F34: 立即造成一次等同于损伤施加者辅助骰的真实伤害，并施加【迟缓】。 | G34: 通道入口 | H34: 在进入该地块时，脱离战场，并在下一回合出现于对应的通道出口
F35: 元素损伤爆发期间，【眩晕】，持续至该角色回合开始1次。 | G35: 通道出口 | H35: 在进入该地块时，脱离战场，并在下一回合出现于对应的通道入口
G36: 医疗地块 | H36: 位于该地块的单位，获得【亲和】
G37: 防御地块 | H37: 位于该地块的单位，获得物理抗性+10

Sheet 主要特质表
A1: 种族特质 | E1: 文化特质 | I1: 工作特质
A2: 特质名称 | B2: 点数花费 | C2: 特质描述 | D2: 特质效果 | E2: 特质名称 | F2: 点数花费 | G2: 特质描述 | H2: 特质效果 | I2: 特质名称 | J2: 点数花费 | K2: 特质描述 | L2: 特质效果
A3: 菲林（猫） | B3: 0 | C3: 感官敏锐、大多生有尖耳和长尾的菲林，与佩洛、黎博利并列为泰拉人数最多、族群分布最广的种族之一。一句出处不可考的高卢谚语是这么说的：“足迹所至，菲林所在。”因历史缘故，维多利亚拥有相当广泛的菲林人口分布，是这片大地上菲林们的主要聚集地。 菲林族群最主要的体貌特征就是他们的尖耳与长尾，二者不仅是身体器官的一部分，也是他们表达自身情绪的工具。尽管也存在两耳浑圆、尾巴短小的特例，但这在菲林族群中仅占少数。普遍而言，菲林的感官发达，有着较好的肢体协调能力。一部分菲林拥有并不十分显著但颇为独特的遗传特征——他们的瞳孔在不同光线环境下会发生形态上的微妙变化。 人尽皆知的是，由于庞大的人口基数以及优秀的适应能力，菲林在漫长的繁衍迁徙中成了泰拉分布最广泛的族群之一。在那个无论神民还是先民都需要一个名称来确定自我的时代，“菲林”囊括了几乎所有以尖耳长尾、感官发达为突出特征的个体，虽然族群的不同分支之间存在着鲜明的外貌差异 | D3: 个人魅力+2、经验智慧+1、反应机动+2 特质【迷人】、【觉察者】消耗的特质点-5 修正因子【感官强化（视觉）】消耗的特质点-5 | E3: 高卢的追忆 | F3: 0 | G3: 你出身于泰拉最为强盛的国家——高卢，至少在你的记忆里，它一向如此，它永远如此。在高卢毁灭后，你也许被迫投身入其他国家寻求庇护，但高卢的强盛依然在你的记忆中占有重要的地位。 | H3: 个人魅力+1 经济评级-10 获得附加技能：高卢语，初始技能值为10 | I3: 工业从业者 | J3: 0 | K3: 你通过从事第二产业的相关工作来维持自己的生活。第二产业即工业，即对是对自然资源开采和对各种原材料加工的社会物质生产部门。这包括如注塑工、操作工、压铆工、缝纫工、焊工的专业工作，也包括了机械，电子，建筑等具体工程项目的设计与维护工作。 | L3: 获得技术资质：等级提升时，技术+1 手工工艺+3、机械工程+2、电子工程+1、妙手+1
A4: 佩洛（狗） | B4: 0 | C4: 佩洛是分布最广、人教最多的泰拉种族之一，从萨尔贡帝国到萨来地区，从玻利瓦尔到东国，到处都能看到他们的身影。目前，玻利瓦尔地区人数最多的种族就是佩洛。 许多人无法直接靠外貌分辨佩洛、鲁珀、沃尔珀和瑞柏巴。这几者的分类问题可说是伴随着人类的历史而一直存在。最新的研究成果表明，在文字出现之前的远古时代，这几个种族确实是被统称为“佩洛”的。 佩洛的人口基数十分庞大，这其中包括了神民和先民的众多分支。如今，奎尔莎、刻俄柏洛斯和乌瑞狄姆等神民分支大都与先民佩洛一起居住，佩洛以外的人很难直接分辨出他们之间的差别，但他们都注重维持良好的人际关系，总是尝试着友善待人 | D4: 生理耐受+1、个人魅力+2、反应机动+2 特质【共情者】消耗的特质点-5 修正因子【感官强化（嗅觉）】、【识别性知觉（嗅觉）】消耗的特质点-5 | E4: 乌萨斯的怒吼 | F4: 5 | G4: 你出身于将战争与征服刻入血液的军事帝国——乌萨斯。恶劣的自然环境并未摧垮乌萨斯人的意志，而是将他们锻造为坚冰般的战士。在内部，陈腐的脓血逼停了帝国扩张的脚步。所有人都看得出来这一点：乌萨斯的变革不日便会到来。 | H4: 等级提升时，生命值上限+2 与特质【耐寒】绑定 获得附加技能：乌萨斯语，初始技能值为10 | I4: 农业从业者 | J4: 0 | K4: 你通过从事第一产业的相关工作来维持自己的生活。第一产业指利用生物的自然生长和自我繁殖的特性，人为控制其生长和繁殖过程，生产出人类所需要的不必经过深度加工就可消费的产品或工业原料的一类行业。这包括分散生产的农民，以及工业生产模式下的农业、牧业、林业、水产养殖业等。 | L4: 获得灵巧资质：等级提升时，灵巧+1 农林渔牧+4、手工工艺+2、妙手+2
A5: 鲁珀（狼） | B5: 0 | C5: 莱塔尼亚东方的叙拉古以鲁珀为主体种族。尽管鲁珀在乌萨斯、维多利亚等国家也有少量分布，但人们对鲁珀的认知常常与叙拉古的家族文化绑定。 鲁珀的生理特征与佩洛差距甚小，但鲁珀是最早从“佩洛”的概念中被区分出来的种族，也是最不容易被误认为佩洛的种族，这很可能与鲁珀独特的文化传统有关。 生活在叙拉古的鲁珀拥有很强的家族观念，一些家族中的所有鲁珀会将尾巴染成同样的颜色，或在耳尖打上同样的记号，以此表明家族身份。但不同于佩洛，家族观念并不使鲁珀倾向于友善待人,反而使他们产生了高度排外的意识。 | D5: 生理耐受+1、反应机动+2、敏捷+1、灵巧+2 特质【迅捷步伐】、【觉察者】、【追踪专家】消耗的特质点-5 修正因子【感官强化（嗅觉）】、【识别性知觉（嗅觉）】消耗的特质点-5 | E5: 乌萨斯的怒吼. 严酷训练 | F5: 25 | G5: 附加限制：/ 描述：战斗与战争是每个乌萨斯人都熟悉的词汇，你从乌萨斯严酷的军事教育中领会到了这一点。 | H5: 生理耐受+1、力量+1 与特质【耐寒】绑定 获得附加技能：乌萨斯语，初始技能值为10 等级提升时，生命值上限+2 | I5: 服务业从业者 | J5: 0 | K5: 你通过从事服务业相关工作来维持自己的生活。服务业的主要工作内容包括了一些专门化的，为其他个体的生活提供服务，以及为工业和农业的生产提供服务的产业。例如管家，仆役，主播，运维团队等。 | L5: 获得情感资质：等级提升时，情感+1 妙手+2、取悦+1、交涉+2、心理+2
A6: 沃尔珀（狐） | B6: 0 | C6: 由于生理区别极其细微，直到今天，沃尔珀在相当多的地区仍会被误认为是佩洛。在大多数时候，这些被误认的沃尔珀也并不会因为自己被冠以其他种族之名而感到身受冒犯。也正是因此，沃尔珀在泰拉的分布统计并不可信，但从整体来看，生活在各地的沃尔珀占当地总人口的比例还是比较低的。 在各类种族中，沃尔珀属于体型较为中等的类型。沃尔珀的反应速度以及身体柔韧性都名列前茅，而且善于在复杂环境下侦察并感知危险，经过训练后也有着不凡的战斗能力。早在古老的时代，一些沃尔珀就被记载为“佩洛中较为灵敏的一支”，成为各部族挑选斥候与信使时最优质的人选。 沃尔珀也有神民和先民的分支，其中最为著名的神民分支便是如今多生活在遥远东国的九尾沃尔珀，相传九尾沃尔珀和东国的上层家族有关系，但具体的情况我们尚不得而知。而除九尾沃尔珀以外，卡纳尔、弗瑞拉等鲜为人知的名字都是沃尔珀神民表列中的一员。 | D6: 个人魅力+2、经验智慧+1、反应机动+1、灵巧+3 特质【共情者】、【迷人】、【觉察者】、【高速反应】消耗的特质点-5 修正因子【感官强化（嗅觉）】消耗的特质点-5 | E6: 维多利亚的荣耀 | F6: 0 | G6: 你出身于泰拉大陆目前最强大的国家——维多利亚，并且毫无争议地以“维多利亚人”自居。但除了对自己的国家拥有更强的自尊心以外，你并没有从这个身份中得到什么好处。 | H6: 获得附加技能：维多利亚语，初始技能值为10 | I6: 医生卫护人员 | J6: 0 | K6: 你通过从事医疗护理的相关工作，或是对其他人提供医疗护理服务来维持自己的生活。医疗护理相关工作一般为使用医学知识为患者进行救治或缓解病情；对各种医疗机械进行操作与检测；对伤者进行紧急救治与诊断等。这包括如医生、医护技术员、急救人员与护工等职业的工作职责，也包括对矿石病感染的紧急阻断、内外伤的诊断与治疗、开放性创口的缝合与包扎、常规伤势的固定与止血等工作能力。 | L6: 获得灵巧资质：等级提升时，灵巧+1 急救+3、妙手+2、心理+1、医药学+3、支援技术+1
A7: 瑞柏巴（鬣狗） | B7: 0 | C7: 瑞柏巴是泰拉大地上人口较为稀少的种族之一，主要生活在萨尔贡地区。他们如鲁珀一般崇尚家族与集群，但并未发展出与此相关的文化与社会结构。 横向比较来看，瑞柏巴的身体素质在泰拉人中属于中等水平，大部分瑞柏巴长着带有绒毛的耳朵和尾巴，部分身上长有斑点或条状花纹。一般而言，瑞柏巴女性的力量显著强于男性。 由于长期生活在萨尔贡的沙漠及附近地区，瑞柏巴普遍有着极为丰富的荒地生活传统，饲养特殊牲畜、野外考察都是他们擅长的工作。他们还拥有着由女性主导的大家族概念，相较于佩洛，瑞珀巴对家族内部的团结和纪律性更为重视。 | D7: 生理耐受+2、物理强度+1、反应机动+1、精神意志+1 特质【团队意识】消耗的特质点-5 修正因子【感官强化（嗅觉）】、【环境适应（荒原）】消耗的特质点-5 | E7: 维多利亚的荣耀.贵族爵位 | F7: 10 | G7: 附加限制：角色在创建完毕后的经济评级不可低于40 描述：你的家族在维多利亚是曾受阿斯兰王册封的显贵，并且这份显贵也有你一份。根据你家族的重要与荣耀程度，你可能会是一位男爵、子爵，或是伯爵，并且拥有一小块地产。 | H7: 获得附加技能：维多利亚语，初始技能值为10 经济评级+10 与显贵人物进行交涉时，交涉类技能检定的检定骰面升级，与劳苦大众进行交涉时，改为检定降级。 | I7: 科研教育人员 | J7: 0 | K7: 你通过从事教育与研究行业的相关工作来维持自己的生活。此类人员的相关工作一般为对他人提供各类知识的教育服务、在各种教育机构内充当教师与管理层、以及通过雇佣形式满足雇主需求进行针对性研究等。这包括了如教授、博士、研究员及科学家（与研究员的区别在于专业性与对课题的独立性）等职业的工作职责。 | L7: 获得教育资质：等级提升时，教育+1 所有教育类技能+1 选择一个教育类技能，该技能+2。加点该技能时无视加点上限。
A8: 阿那缇（鼬） | B8: 0 | C8: 常与山脉绑定的阿纳缇是这片大地上的常见种族，在过去的很长一段时间里，他们常生活在远离平原的山区之中，并对任何拜访的客人都热情相待。 阿纳缇善奔走，许多常人无法越过的崎岖山地他们也能如履平地，这让他们在许多地区成了行商和信使的专业户。伴随着移动城市的发展，他们的业务也从山中转移到了移动城市上。 仍然住在山中的阿纳缇善于在山间土壁上开凿别具一格的洞穴式居所，它不同于在移动城市或者在其他定居点中看到的建筑——整个洞穴系统依山体而建，挖掘多于建构。 | D8: 反应机动+2、经验智慧+1、身法+1 特质【迅捷步伐】、【飞檐走壁】、【平稳落地】消耗的特质点-5 | E8: 塔拉的焰火 | F8: -15 | G8: 你出身于泰拉大陆目前最强大的国家——维多利亚，但你并非维多利亚人，而是出生于盖尔王曾统治的土地之上的“塔拉人”。尽管你们生活在“塔拉下王国”之中，但你们相比于维多利亚人仅是二等公民，也因此难以享受维多利亚的社会资源。 | H8: 经验智慧-1、经济评级-5 获得附加技能：廷盖语，初始技能值为5 获得附加技能：维多利亚语，初始技能值为5 | I8: 政法机关人员 | J8: 0 | K8: 你在一个政府或司法机关中拥有相应编制，通过为政府工作而获得报酬，并以此维持自己的生活。视政体与工作部门的不同，相关的从业人员掌握的能力也存在差异，但他们均学习过政治与法律的基础知识，也拥有对公文的审批与阅读理解能力。 | L8: 获得教育资质：等级提升时，教育+1 政法学+3，经管学+2，社会学+2 选择一个交涉类技能，该技能+2
A9: 卡特斯（兔） | B9: 0 | C9: 泰拉的卡特斯族群主要集中在雷姆必拓的自治州及周边地区，尽管他们在其他国家和地区不算罕见，但没有哪里能像雷姆必拓一样拥有如此众多的卡特斯人口。 卡特斯的长耳和毛绒短尾是他们最令人印象深刻的外貌特征，发达的听觉器官以及灵活的反应力弥补了平均体型较小带来的一系列不足。我们有理由相信，正是这些得天独厚的优势帮助卡特斯族群在部落时代以前生存下来，进而形成庞大的人口。 为了弥补个体身体素质的不足，生活在如今之雷姆必拓的卡特斯们普遍选择了群聚群居的社会生活方式，在部落时代形成了富有活力的屯堡聚落。成员数目众多的联合家庭成了巩固内部关系的凝聚核心，同时也形成了极具特色的“卡特斯大家庭”文化——家庭成员的团结友爱深受重视。 | D9: 个人魅力+1、经验智慧+1、反应机动+3 身高、体重标准值-20% 特质【觉察者】、【团队意识】消耗的特质点-5 修正因子【感官强化（听觉）】消耗的特质点-5 | E9: 塔拉的焰火.深池 | F9: -5 | G9: 附加限制：/ 描述：在塔拉的芦苇荡中潜藏着一支意图重铸塔拉荣光的反抗势力，而你正是他们——“深池”中的一员。 | H9: 经验智慧-1、经济评级-5、物理强度/源石技艺适应性+1 获得附加技能：廷盖语，初始技能值为5 获得附加技能：维多利亚语，初始技能值为5 你可以无视【沼泽】的地形特性效果 | I9: 战斗人员 | J9: 0 | K9: 你使用自身的身体素质与战斗相关的能力来向他人换取报酬，或是直接以此为生。视雇佣者与工作性质的不同，你可能是国家军队中的一名士兵或军官，或是受雇于公司的安保与情报人员，或是更为独立的雇佣兵与杀手等，献身于一些暴力社会组织（诸如锈锤、整合运动）的暴徒也属于此类人员。用各种手段伤害他人，或是对建筑与环境造成严重破坏的能力是战斗人员应当掌握的。 | L9: 选择一个非战斗属性的副属性，获得该副属性资质：等级提升时，该副属性+1 创建角色时，可以额外获取价值至多为15源石锭的配件。 每个模组开始时，可以额外获取价值至多为5源石锭的投掷物与消耗品。
A10: 札拉克（鼠） | B10: 0 | C10: 即使和菲林或黎博利相比，札拉克人口数量也堪称庞大，他们广泛分布在泰拉各地，从玻利瓦尔到雷姆必拓都可以找到。近年来，也有相当数量的札拉克选择前往哥伦比亚生活。 就泰拉平均水平而言，札拉克体型普遍较小，动作大多较为灵活。他们往往具备优异的听力和反应能力，对空气的振动、气流的改变也很敏感，经常从事信使工作。同样，在天灾信使的队伍中也常常可以发现札拉克的身影。 札拉克一般头顶生有一对显眼的圆耳朵。对于一小部分札拉克而言，这对耳朵往往又因为毛发而显得尖。札拉克耳朵上的这一束束毛发并非长自头皮，而是生长自耳朵本身，又被称为“耳簇”（一小部分菲林同样生有这种毛发）。在卡西米尔到谢拉格一带生活的札拉克往往有着更浓密的耳簇和巨大的毛茸茸尾巴；而到了再南方一些、气候更温暖的地方，他们耳朵和尾巴上的毛发就会变得细小。 | D10: 反应机动+3、经验智慧+1、精神意志+1、敏捷+1、洞察+2 生理耐受-1、力量-1 身高、体重标准值-20% 特质【悄无声息】、【迅捷步伐】、【觉察者】消耗的特质点-5 修正因子【感官强化（听觉）】、【识别性知觉（听觉）】消耗的特质点-5 | E10: 莱塔尼亚的优雅 | F10: 15 | G10: 你出身于千术万法的故乡——莱塔尼亚。法术辉光与艺术氛围如空气一般弥散在这个国家的每一处角落，并显化为了外人对这个国家最为刻板的印象，莱塔尼亚人深知这一点——他们为此骄傲。 | H10: 源石技艺适应性+1，教育/情感+2 获得附加技能：莱塔尼亚语，初始技能值为10 | I10: 宗教人员 | J10: 0 | K10: 你以宗教活动和教会管理为主要职业，并从中得到了维持自己生活的报酬。因教义和宗教所处社会环境的不同，从业者之间的职能差异与工作范围存在着相当大的差异。常见如东/炎二国的道士与僧侣、伊比利亚审判庭的教徒、耶拉冈德的信徒以及遍布大地的拉特兰教徒等。位于萨米的雪祀以及深海教徒等虽十分罕见，但也均属于宗教人员的行列。 | L10: 获得情感资质：等级提升时，情感+1 心理+3、教育+2、政法学+2 选择一个交涉类技能，该技能+3
A11: 斐迪亚（蛇） | B11: 0 | C11: 斐迪亚是泰拉较不常见的种族之一，但他们的居所遍布大地。不论是萨米的雪原上、乌萨斯的森林中，还是萨尔贡的黄土里、维多利亚的楼宇间，只要费力寻找一番，都可以找到斐迪亚的踪迹。 斐迪亚的特点是仅生有一对的尖耳和带有鳞片的长尾。他们的身高普遍高于泰拉人平均水平，而体重又往往处于平均水平以下，这让他们获得了“瘦弱无力”的刻板印象，这当然是没有依据的，他们的身体素质整体而言完全位于平均范围之内。 绝大多数斐迪亚都没有毒。如果说斐迪亚有什么真正的特点，那应该是他们擅长长期专注于某一件事，很容易找到一个人生的目标。 | D11: 经验智慧+1、反应机动+1、精神意志+1、心理+1、战术+1、镇定+2 身高标准值+10% 体重标准值-10% 特质【水性】、【悄无声息】、【迅捷步伐】消耗的特质点-5 | E11: 莱塔尼亚的优雅.高塔贵族 | F11: 25 | G11: 附加限制：角色在创建完毕后的经济评级不可低于40 描述：你的宗族世代生活在莱塔尼亚的高塔中，以钻研知识，追求艺术，教导领民为己任。根据你的经济评级，你可能是子爵，侯爵，甚至选帝侯，并且在莱塔尼亚毫无疑义地作为贵族抛头露面。 | H11: 源石技艺适应性+1，教育/情感+2、经济评级+10 获得附加技能：莱塔尼亚语，初始技能值为10 与显贵人物进行交涉时，交涉类技能检定的检定骰面升级，与劳苦大众进行交涉时，改为检定骰面降级。 | I11: 宗教人员.武装朝圣 | J11: 15 | K11: 从物理上进行真刀真枪的斗争对于你的信仰和神职来说是不可避免的。你可能是一位伊比利亚的执裁官或是萨米的雪祀，进而使得你必须用武器的批判作为批判的武器之补充。 | L11: 选择一个非战斗属性的副属性，获得该副属性资质：等级提升时，该副属性+1 与你的信仰所公认的敌人进行战斗时，你的战斗技能检定获得一个奖励骰。 特质【崇高信念】、【视死如归】消耗的特质点×50%
A12: 萨弗拉（蜥蜴） | B12: 0 | C12: 萨弗拉以沙漠为家，他们大多生活在萨尔贡，也有一部分迁居雷姆必拓。他们喜欢日照充足、可以长时间享受阳光的地方 萨弗拉是一支身体和尾巴都长有鳞片的种族。他们身手矫健，眼光敏锐，几乎可说是天生的猎手。有很大一部分萨弗拉全身都被鳞片覆盖，有改变体表鳞片颜色的能耐。搭配合适的服装，他们可以做到和沙漠、荒地等周边环境完全融为一体。 在一般认识中，萨弗拉最大的两个特点是“长寿”和“来自萨尔贡”。虽然二者皆为事实，但不幸的是，它们在大众文化中被不公正地夸张了。 | D12: 生理耐受+1、经验智慧+1、反应机动+2、乔装+1、潜行+1 特质【悄无声息】、【长寿】消耗的特质点-5 修正因子【感官强化（视觉）】、【天然迷彩】消耗的特质点-5 | E12: 大炎的沧桑 | F12: 15 | G12: 你出身于一片沧桑广阔，包罗万象的土地——炎。在历经了动乱与变革之后，大炎依然稳居于这片大地的前列。古老的制度没有成为新生事物的阻碍，大炎的子民将在新时代里缔造更为辉煌的历史。 | H12: 经验智慧+1，教育+2 获得附加技能：炎语，初始技能值为10 | I12: 无固定职业 | J12: 0 | K12: 你尚未拥有、或是已经失去了常规意义上的社会职业身份。你仍然能通过诸如家族的帮助、遗产、捐赠等方式维持生活，或是你因自身独特的能力而无需社会资源独自生存。 | L12: 选择一个非战斗属性的副属性，获得该副属性资质：等级提升时，该副属性+1 社交点数+5 经济评级-5 社交点数+5/获得一个任意人脉，该人脉价值不高于5
A13: 黎博利（鸟） | B13: 0 | C13: “黎博利”是对体表生有羽毛的神民和先民的统称。由于这一称呼所指代人群的广泛性，黎博利现在是泰拉最庞大的族群之一，广泛分布在泰拉各地。黎博利是构成哥伦比亚多元种族的主体种族之一，伊比利亚和拉特兰也有大量的黎博利人口。 黎博利最大的特征是生在体表的羽毛。通常来说，黎博利的头部和躯干的一部分毛发会被羽毛所替代。黎博利的平均身高在这片大地的众多种族中处于中游，但女性会更为娇小。他们的体重则因种族原因要轻于其他种族。黎博利的身体素质较为普通，没有什么特别之处。 “黎博利”一词所指代的这一族群人口基数很大，而且同时包括神民和先民，因此种族分支也较多，他们经常发现彼此之间存在着的小小不同。最广为人知的黎博利神民是骏鹰，他们在外表上同时拥有黎博利的羽毛和库兰塔的尾巴，因建立了骏鹰王国而得以扬名。 | D13: 反应机动+1、敏捷+1、灵巧+2、身法+1 体重标准值-10% 特质【平稳落地】、【觉察者】、【迅捷步伐】、【高速反应】消耗的特质点-5 修正因子【感官强化（视觉）】消耗的特质点-5 | E13: 大炎的沧桑. 拜师学艺 | F13: 35 | G13: 附加限制：/ 描述：你试图在卧虎藏龙的大炎内寻找一位老师，或只是某个武术馆的教导以提高自己的战斗水平，并且学有所成。 | H13: 经验智慧+1，教育+2、格斗+1 获得附加技能：炎语，初始技能值为10 | I13: 非劳动所得 | J13: 0 | K13: 你无需通过出卖自身劳动力而换得报酬，而是通过掠夺、偷窃、剥削等方式从他人手中取得物资并以此生存。常见如窃贼、黑帮、拥有自身领地的贵族、以及占据了大量生产要素与生产资料的同时又不事生产的企业家等。 | L13: 获得镇定/洞察资质(其中之一）：等级提升时，镇定/洞察+1 与你的SN商议，通过个人资产、人脉、技能补正或特质来解释你的生存之道！
A14: 安努拉（蛙） | B14: 0 | C14: 主要居住在萨尔贡和玻利瓦尔的安努拉是较为少见的存在，绝大多数其他地区的泰拉人都对他们没什么了解。安努拉们喜欢潮湿而又水草丰沛的地方，近年来迁去移动城市的安努拉也都倾向于定居在绿化率较高且水道治理良好的城市。 大部分安努拉传承着有关潜行和隐身的源石技艺，而少部分则可以使用自身分泌的独特剧毒物质作为强大的武器来攻击敌人。对此略有了解的人可能会担心，只要与安努拉接触就会导致严重的中毒反应,但事实上安努拉可以自由控制自身毒素的分泌。 阿达克利斯与安努拉同为雨林住民，长久以来这两者之间也都保持着良好的关系。擅长体力活的阿达克利斯会帮助安努拉建设新的居所和其他建筑，而安努拉则会以负责村庄规划和装修作为回报。此外，阿达克利斯和安努拉一同举办游泳比赛来庆祝节日也是并不少见的场景。 | D14: 反应机动+2、精神意志+2、灵巧+2、镇定+2 特质【水性】、【悄无声息】、【毒液分泌】消耗的特质点-5 | E14: 哥伦比亚的创想 | F14: 10 | G14: 你出身于年轻但却足够引人注目的新兴国家——哥伦比亚。创新、创意、创想，数之不尽的“新东西”从蓝卡坞与特里蒙中喷涌而出，这个国家势必要站在技术与发展的最前沿。一再膨胀的金融数字与永不停歇的拓荒浪潮令所有人都将目光放在了它描绘的美好未来上，至于感染者的血汗与拓荒者的尸骨，只不过是这个国家阴影中的“小数字”。 | H14: 经验智慧+1 获得附加技能：哥伦比亚语，初始技能值为10 | I14: 自定义工作
A15: 曼提柯（蝎） | B15: 0 | C15: 曼提柯是泰拉种族之一，体表生有双翼，躯干带有节肢状甲壳尾部。基本上所有曼提柯都居住在萨尔贡境内，非常少见。 一般而言，曼提柯最显著的外表特征有两点：一是头部左右两侧长有成对的膜状翅；二是躯干有延伸出来的节肢状甲壳尾部，通常尾部的最后一节是长有一根刺针的尾节。曼提柯的平均身高大概与泰拉平均身高保持一致，女性略矮于男性。他们的身体素质较为优秀，部分曼提柯的尾针上可能会带有毒液。 曼提柯大多极为避世，他们素来有崇尚低调与隐蔽的文化传统。因此，曼提柯一直与其他种族保持着距离。在移动城市出现后，曼提柯们选择不进入移动城市而保持以往的生活状态继续生活。如今的曼提柯基本都生活在萨尔贡境内远离移动城市的偏僻地区。 | D15: 生理耐受+1、反应机动+2、敏捷+1、潜行+2 与特质【固有武器】绑定 特质【悄无声息】、【毒液分泌】消耗的特质点-5 修正因子【环境适应（荒原）】消耗的特质点-5 | E15: 哥伦比亚的创想.感染者医疗保险 | F15: 10 | G15: 附加限制：角色为感染者时；该修正因子强制选择 描述：在哥伦比亚，衡量人价值的指标被简化为“价值”本身。没有人在乎感染者这个身份，但哥伦比亚并不介意从它的身上汲取更多的血钱。 | H15: 经验智慧+1、经济评级-10 获得附加技能：哥伦比亚语，初始技能值为10 进入新的感染阶段时，经济评级-5
A16: 阿达克利斯（鳄鱼） | B16: 0 | C16: 崇尚力量的阿达克利斯以雨林为家，他们大多生活在萨尔贡东部的湿润之地。在这里，有着标志性的尾巴的他们以部落的形式居住在沿河的地带，并形成了属于自己的身份认知。 阿达克利斯有着出众的水中行动能力，游泳是大多数阿达克利斯与生俱来的天赋，这使他们常常选择从水中向敌人或猎物发起伏击。走出雨林的阿达克利斯往往被当作纯粹的武者，却很少有人知道，他们在水中的灵巧程度是常人难以企及的。 阿达克利斯常常表现出对自身能力的充分自信，有相当一部分阿达克利斯喜欢自称“提亚卡乌”，意为“骁勇善战之人”。这种古老的身份认同自萨尔贡强盛时代便开始流传，一些颇具可信度的记载指出，这种认同来自古代萨尔贡皇帝对于阿达克利斯勇士的一次封赏。 | D16: 生理耐受+1、物理强度+2、力量+1、灵巧+1 身高、体重标准值+20% 特质【水性】、【体能充沛】、【坚韧体魄】、【快速愈合】、【额外手】消耗的特质点-5 | E16: 哥伦比亚的创想.拓荒者 | F16: 5 | G16: 附加限制：/ 描述：哥伦比亚始于拓荒，因此它鼓励任何人投身入拓荒的浪潮。加入拓荒队列的感染者能够免于强制性的保险金需求，但只有最为鲁莽的愣头青才会轻信于它的宣传，从而对骸骨荒原上遍布的干尸视若无睹。 | H16: 经验智慧+1、技术+3、经济评级-10 获得附加技能：哥伦比亚语，初始技能值为10 | I16: 已选特质消耗 | J16: =IFERROR(VLOOKUP(主卡!X14,I3:J14,2,0),"")
A17: 乌萨斯（熊） | B17: 0 | C17: 乌萨斯主要居住在泰拉北方的乌萨斯帝国境内，人口众多。此外，乌萨斯在卡西米尔，谢拉格，萨尔贡北部以及炎国等许多地区也多有分布，是较为常见的泰拉种族之一。 高大，强壮和坚忍是人们对乌萨斯的普遍认知。这种认知来源于他们的生理特征，即平均的身高更高，力量更强。此外，大部分的乌萨斯居住在泰拉北方，这些地域漫长的冬天塑造了他们强韧的耐力。 | D17: 生理耐受+2，物理强度+2，精神意志+1 身高，体重标准值+20% 特质【坚韧体魄】、【快速愈合】消耗的特质点-5 修正因子【环境适应（雪原）】消耗的特质点-5
A18: 丰蹄（牛） | B18: 0 | C18: 泰拉西南方的米诺斯以丰蹄为主体种族。除此之外，丰蹄也广泛地分布在炎国、萨尔贡等多平原的国家，是较常见的泰拉种族之一。 大部分时候，人们只知丰蹄强壮，却不知在许多以丰蹄为主体种族的地区，智慧才是更受重视的美德。米诺斯的土地上自古就分布着许多丰蹄聚落。相传，丰蹄们终日沉浸在文艺创作与思想探讨中。这样的生活方式与近旁高度尚武的瑞柏巴部族形成了鲜明的对比。 生活在炎国的丰蹄族群很可能是泰拉最早开始从事农耕生产的群体之一。相较于狩猎采集的生活方式，农耕意味着更高强度的劳动。而相较于其他大多数种族，身强体壮但不甚灵活的丰蹄显然更能适应这种新兴的生活方式。 | D18: 生理耐受+3、物理强度+2、经验智慧+1 反应机动-1 身高、体重标准值+20% 特质【体能充沛】、【坚韧体魄】、【快速愈合】消耗的特质点-5 | E18: 玻利瓦尔的纷争 | F18: -10 | G18: 你出身于饱受战火折磨的焦土——玻利瓦尔。侵略内战与地区割据在这片土地上循环往复。即便已经过去了数百年之久，可玻利瓦尔上空的阴霾从未消散，玻利瓦尔人虽已对战斗习以为常，但如有机会，他们必会将一切悲剧停止。 | H18: 教育-3、经济评级-5 获得附加技能：伊比利亚语/莱塔尼亚语/维多利亚语/哥伦比亚语，初始技能值为10
A19: 塞拉托（犀牛） | B19: 0 | C19: 塞拉托是原本栖息在萨尔贡绿洲的诸多族群之一，以强健的体格著称。近百年来，塞拉托高大的、奔驰的身影开始出现在了泰拉的其他地区。 塞拉托和库兰塔一样善于奔跑，但不经常长途跋涉。比较流行的、也比较为塞拉托所认可的一种说法是，成年之后的塞拉托普遍身材高大，体重也异于其他种族，支撑厚重身躯进行长时间运动所需的能量很可能超乎想象。 塞拉托非常珍视自己头上的角，但他们珍视的方式与众不同。自部落时期以来角就是塞拉托的重要武器，他们爱护角的方式是面对面短途冲锋，用额上的角进行对抗，以此来把角磨砺得更加坚韧。萨尔贡的塞拉托部族迄今为止仍然保留着饲养羽兽的传统爱好，有一类生活在绿洲地区的特别的羽兽对塞拉托似乎有着天然的亲和力。 | D19: 物理强度+2、生理耐受+3、力量+1 敏捷-1 身高、体重标准值+20% 特质【体能充沛】、【坚韧体魄】、【硬肤】消耗的特质点-5 | E19: 玻利瓦尔的纷争.军事传统 | F19: 10 | G19: 附加限制：/ 描述：玻利瓦尔历来拥有全民皆兵的传统，在进行了军事训练后，你拥有了足以踏入玻利瓦尔纷乱战场中的能力。 | H19: 教育-3、经济评级-5、力量+1、敏捷+1 获得附加技能：伊比利亚语/莱塔尼亚语/维多利亚语/哥伦比亚语，初始技能值为10
A20: 库兰塔（马） | B20: 0 | C20: 库兰塔的祖先们选择在泰拉中北部的卡西米尔平原定居后，这支强健善奔的族群便世代在广阔的平原上生活。有不少库兰塔在一千多年前随着梦魇可汗离开了草原，所以如今在泰拉各地都能见到库兰塔的身影。 库兰塔有着相较于泰拉人平均水平来说更为健壮的身体，虽然不如乌萨斯和丰蹄那样强壮，但体能更胜一筹。古代的库兰塔凭借优秀的身体素质，在平原上过着四处迁移的生活。游牧的传统使得库兰塔需要迅速响应随时可能遭到的突袭，因此他们形成了全民习武的军事传统，这就是后来骑士团文化的早期雏形 库兰塔有着数量一般的分支，其中包括神民与先民。最出名的库兰塔神民便是天马与梦魇，两军的对决直至今日也是为人所津津乐道的话题。天马血脉在溃败后便被赶下了国王宝座，变成了骑士贵族；梦魇血脉则在可汗远征失败后四处流浪，据说人们在这片大地上的各地都有可能见到梦魇后裔。 | D20: 生理耐受+2、反应机动+3 身高、体重标准值+10% 特质【体能充沛】、【迅捷步伐】、【高速反应】消耗的特质点-5 | E20: 雷姆必拓的热烈 | F20: 0 | G20: 你出身于顽强且茁壮成长的新生国家——雷姆必拓。它诞生于充满天灾与源石结晶的恶劣荒地中，但也因此得以兴起矿业与工业。相当一部分雷姆必拓的居民原先是各个国家的移民，但当地的卡特斯族群乐于接受这一切，并以热情的态度试图让他们融入到“雷姆必拓”这个大家庭之中。 | H20: 技术+2、经济评级-5 获得附加技能：雷姆必拓语，初始技能值为10
A21: 伊特拉（麝） | B21: 0 | C21: 依特拉大都居住在泰拉那些寒冷的高原山地或者冰原附近。在炎国、谢拉格、乌萨斯和萨米地区的部分地方时常能看见他们的身影，但除此之外的其他地方则很少有依特拉居住。 依特拉的外观与卡普里尼、埃拉菲亚和库兰塔极其相似。依特拉与前两者的区别在于头上的角——依特拉并不会长角。而依特拉与库兰塔相比则在身体素质上略逊一筹。据说依特拉的祖先长有狭长的尖齿，但如今这一特征已不再明显。 在高寒地区的危险生活经历让依特拉这个族群变得多疑和警惕，许多地区的依特拉族群仍然保留着相对排外的传统。谢拉格的依特拉可能是最早开始崇拜耶拉冈德的种族之一，他们在耶拉冈德崇拜传播的历史上产生过很大的影响，许多经文和典籍都是由依特拉撰写和编纂的。 | D21: 生理耐受+2、物理强度+1、个人魅力+2 特质【迅捷步伐】、【迷人】、【高速反应】消耗的特质点-5 | E21: 雷姆必拓的热烈.家庭文化 | F21: 10 | G21: 附加限制：/ 描述：你是雷姆必拓本地的一支大家庭中的一员，或是作为移民融入了雷姆必拓的文化之中。你与你的家人们保持着紧密的联系。 | H21: 技术+2、经济评级-5、社交点数+10 获得附加技能：雷姆必拓语，初始技能值为10
A22: 卡普里尼（羊） | B22: 0 | C22: 卡普里尼是较为常见的泰拉种族之一，主要居住在莱塔尼亚及其周边，亦有不少族群分布在泰拉各地。 卡普里尼以对源石技艺优秀的掌握能力而著称。在很多人心里，每个卡普里尼都是神秘源石技艺的操纵者，但这其实是一种结合了现实依据和美好憧憬的刻板印象。就平均能力而言，卡普里尼确实拥有相较于其他种族更为良好的源石技艺适应性；但就个人而言，卡普里尼中也存在着无法使用源石技艺的个体。 卡普里尼人口最集中的地方就是莱塔尼亚。如今普遍的观点认为，莱塔尼亚热爱艺术文化的风尚与当地的主体种族卡普里尼密切相关。卡普里尼的平均身体素质在各种族中算不上出类拔萃，可能正是这一点造就了他们细腻敏感的精神特点。有理论称这一特点和卡普里尼对源石技艺的卓越适应性能够互为因果。 | D22: 经验智慧+1，源石技艺适应性+2、精神意志+2、情感+2 特质【共情者】消耗的特质点-5 | E22: 东国的浮华 | F22: 0 | G22: 你出身于极东之地，与外界鲜有交流的变革之地——东国。南北两院八大家的分治令这个国家的政治结构纷乱如麻，但东国的居民早已习惯了在这样的环境下生活。东国为其他国家留下的印象不仅有繁荣的电子艺术文化，还有在南北两院的摩擦中艰难维系的微妙政治平衡，而对于东国的居民而言，二者都是生活中难以忽视的组成部分。 | H22: 获得附加技能：东国语，初始技能值为10
A23: 埃拉菲亚（鹿） | B23: 0 | C23: 泰拉极北的萨米以埃拉菲亚为主体种族。除此之外，埃拉菲亚也广泛地分布在乌萨斯、卡西米尔、菜塔尼亚等多林地的国家，是较常见的泰拉种族之一。 事实上，如今主要分布在乌萨斯、莱塔尼亚、卡西米尔等多林地国家的埃拉菲亚大都源自萨米地区，而对自然的亲近乃至尊崇正是萨米地区独特的文化习惯。随着城市的扩张，大多源自萨米的埃拉菲亚已经遗忘了自然，但在一些国家的边远地区，仍有少数以埃拉菲亚为主体的聚落在林中过着游猎的生活。 此外，在萨米地区的一些埃拉菲亚部族中，角被认为是感知自然的媒介。那里有些个体的角甚至终其一生都保持着缓慢生长，并具有知觉。 | D23: 个人魅力+1、经验智慧+1、精神意志+3 特质【迷人】、【共情者】消耗的特质点-5 修正因子【装饰性器官（角）】消耗的特质点-5 | E23: 东国的浮华.忍客 | F23: 20 | G23: 附加限制：角色在创建完毕后的电子工程技能值不低于8 描述：忍客是东国特有的一种职业，他们善于利用电子工具与信息媒介，改写并操控它们，以此骇入企业或个人的计算机、网络信息库或是电子机械中实现自身目的，你同样拥有这些能力。 | H23: 获得附加技能：东国语，初始技能值为10 经验智慧+1、电子工程+2
A24: 匹特拉姆（龟） | B24: 0 | C24: 匹特拉姆是极其少见的种族，许多人甚至从未听说过泰拉还存在这样一个名叫“匹特拉姆”的种族。事实上，匹特拉姆大都避世并且居住在水源丰富的地区。 匹特拉姆的生理构造极其独特，没有尾巴、角或者鳞片等具有明显特点的外观，极少出现在公众视野之中，这可能是因为源石对他们身体的改造更加彻底。 大部分匹特拉姆聚落都掌握一些极其高明并且不为外人所知的熔炼和生产技术，匹特拉姆中有许多出色的工匠和材料学家（即便他们没有学习过任何现代科学的知识）。据古萨尔贡的史料记载，匹特拉姆们制造金属等材料都具有极佳的性能，他们却拒绝向王酋分享相关的技术和知识。炎国、维多利亚和伊比利亚沿海地区的部分匹特拉姆村庄和上岸的阿戈尔们走得很近，有些还会互称对方为“同胞”， | D24: 生理耐受+2，经验智慧+3、精神意志+2、技术+4、镇定+2、手工工艺+2 反应机动-2、敏捷-2、灵巧-2 与特质【迟钝】绑定 特质【硬肤】、【制造专家】、【长寿】消耗的特质点-5 | E24: 卡西米尔的霓虹 | F24: 0 | G24: 你出身于传统文化走向没落，而金融与经济日益兴盛的骑士与商业之国——卡西米尔。即使骑士文化被解构消磨，卡西米尔的军事实力依然不容小觑，而对于卡西米尔人而言，新生的竞技骑士文化不仅是卡西米尔金融经济的一大支点，还是现代卡西米尔文化中最为核心的部分。 | H24: 获得附加技能：卡西米尔语，初始技能值为10
A25: 皮洛萨（树獭） | B25: -40 | C25: 极少出现，极为罕见，只有传闻的种族——他们的特殊之处往往能使自身成为人群当中的焦点，但仍有许多人甚至未曾听闻过这个种族，这足以说明他们的罕见。 出于某种未知原因的种族特性，皮诺萨行动极其迟缓，却也因此拥有远超常人的耐心和执着。人们往往将皮洛萨视为只在传闻与谎言中出现的虚构种族，但事实上，这片大地无奇不有，即使是皮洛萨也能在其中找到能够令自己安居的住地。 | D25: 精神意志+3、经验智慧+3、镇定+6、情感+2 反应机动-5、身法-1 与特质【嗜睡】、【迟钝】绑定 | E25: 卡西米尔的霓虹.竞技骑士 | F25: 10 | G25: 附加限制：角色在创建完毕后拥有任意一项技能值不低于 4 的战斗技能。 描述：你依靠自己强大的战斗能力（或者说，表演能力）成为了一名竞技骑士，并以此赢得粉丝与经纪人的信赖。 | H25: 获得附加技能：卡西米尔语，初始技能值为10 取悦+2 等级提升时，经济评级+1
A26: 瓦伊凡（双足飞龙） | B26: 0 | C26: 瓦伊凡主要居住在萨尔贡、维多利亚和瓦伊凡联盟（有争议的）控制区内。近年来有不少瓦伊凡在佣兵生涯结束后选择在其他国家和地区定居。 瓦伊凡和德拉克之间的关系是个有趣的话题，这两者在外表上有许多相似之处，最大的区别在于对源石技艺的掌控能力上，德拉克普遍远强于瓦伊凡。在阿斯兰征服时期，瓦伊凡被阿斯兰击败，但阿斯兰认可了瓦伊凡强大的实力，便将大量领土赏赐给各瓦伊凡部落，并允许瓦伊凡成为阿斯兰的护卫。后来，一支阿斯兰皇室分支远征维多利亚时带走了部分瓦伊凡，后者就是如今维多利亚瓦伊凡的先辈。 大部分传统的瓦伊凡会让年轻一代接受严格的战斗培训和作为护卫的专项训练，将其中资质最好的送去萨尔贡宫廷担任阿斯兰皇族的贴身侍卫。落选者中的大部分则会靠着自身的本领成为雇佣兵，这便是瓦伊凡佣兵传统的来源。 | D26: 生理耐受+2、物理强度+2、格斗+1、 身高、体重标准值+20% 与特质【体能充沛】绑定 特质【坚韧体魄】消耗的特质点-5 | E26: 卡西米尔的霓虹.旧日荣光 | F26: 15 | G26: 附加限制：/ 描述：你是某个古老骑士家族中的一员，并且从长辈的教育中学习了身为骑士所应当掌握的知识与能力。你的家族也许开始没落，也许遗泽尚存，不论如何，它的名号都足以庇护你的成长。 | H26: 教育+2、经验智慧+1 特质【高贵】消耗的社交点×50%
A27: 龙（东方龙） | B27: 0 | C27: 龙是炎国独有的神民种族。数千年来，他们生活在大地的东方，他们缔造了古老的文明，他们统治着一个繁荣且开明的帝国。 凡提及“龙”，炎国皇室的祖先“真龙”是绝对绕不过的人物。这位祖先对炎国的深远影响毋庸置疑，国家以他的名字命名，炎国的皇帝继承他真龙的名号，皇室家族也自称为“真龙一族”。实际上，除了真龙一族之外，炎国大地上还生活着许多其他的龙，他们虽然不是皇族，但也都以龙自居，也都奉炎氏这一位真龙为祖先，因为他们也都是炎氏赐姓的百氏后代。“真龙”这一炎国词语中的“真”也并非与“伪”相对，所谓的“真”表达的是人们对共同祖先、传奇领袖的一种崇高致意。 龙族百姓热爱自己的历史，他们不论老少都或多或少知晓自己祖先的故事，并骄傲地把这些历史和传统视作珍宝。这与龙，或者说炎国自炎氏以来就有的、用文字保存历史的传统有关。 | D27: 经验智慧+3、精神意志+1、源石技艺适应性+1、教育+4 | E27: 卡西米尔的霓虹.竞技骑士.旧日荣光 | F27: 25 | G27: 附加限制：/ 描述：你是某个古老骑士家族中的一员，并且从长辈的教育中学习了身为骑士所应当掌握的知识与能力。你的家族也许开始没落，也许遗泽尚存，不论如何，它的名号都足以庇护你的成长。 后来，你依靠自己强大的战斗能力（或者说，表演能力）成为了一名竞技骑士，并以此赢得粉丝与经纪人的信赖。 | H27: 获得附加技能：卡西米尔语，初始技能值为10 教育+2、经验智慧+1、取悦+2 特质【高贵】消耗的社交点×50% 等级提升时，经济评级+1
A28: 德拉克（火龙） | B28: 40 | C28: 德拉克是在泰拉历史舞台上扮演了重要角色的神民种族。他们人数稀少，零散地分布在泰拉各个地区，每个地区的德拉克族群都有非常鲜明的地域特征。 从现实的角度来看，德拉克的人口并不多，但他们大多拥有华丽的角和尾巴，就算身处人群之中，人们也很难把他们认错。近百年以来，随着泰拉各国、各个种族之间的交流日益密切，已有可信的数据证明德拉克在源石技艺适应性和某些身体素质方面确实具有优势。 另一方面，“德拉克”这一名称的指代及其认同曾经是极度松散的，直到近一千年来核心圈才形成了对这一强大族群的统称——这同样解释了他们身上的传说为何会如此纷繁复杂。分布在不同地区的德拉克族群有着许多共性，但他们之间的区别同样显著：譬如曾在伦蒂尼姆与狮王分享权力的龙之家族和塔拉的盖尔王血脉，相信任何了解维多利亚历史的人都不会轻易把他们混为一谈。 | D28: 生理耐受+1、源石技艺适应性+3、精神意志+1 身高、体重标准值+20% 与修正因子【装饰性器官（角；尾）】绑定 特质【高贵】消耗的社交点×50% 使用火焰源石技艺进行相关检定时，获得两个奖励骰。 | E28: 萨尔贡的慷慨 | F28: -10 | G28: 你出身于古老且神秘的土地——萨尔贡。这片广袤的地域被帕夏与王酋们分隔为无数的碎块，但他们均服从于萨尔贡的君主，万王之王的统治。萨尔贡人并不热衷于向外界的探索，而更习于在雨林与荒漠中自给自足，外界常常将之视为封闭与愚昧，但他们并不知道这片土地究竟蕴藏了多少财富与秘密。 | H28: 教育-2、经济评级-5 获得附加技能：萨尔贡语，初始技能值为10
A29: 麒麟（麒麟） | B29: 40 | C29: 遥远东方的炎国大地孕育出了许多独特的种族，麒麟就是其中的一支他们人数稀少，但地位崇高，历来是炎国朝堂与府衙的常客。 麒麟的外貌特征与埃拉菲亚非常相似，但是和埃拉菲亚给人们的出世印象不同，作为神民种族的麒麟反而要入世得多，他们在炎国的社会中历来享有很高的威望。 麒麟术师所使用的招引雷电的源石技艺传承至今，被称为“雷法”。这一派独特的源石技艺曾一度仅为这位术师的后人所掌握，他们以祖先的职业为姓，是为“祝氏麒麟”。历代真龙的朝廷里都有麒麟担任要职，通常是司掌法律、行使惩戒一类的高官，各个麒麟宗族也通常更愿意承担相关的职责，似乎早就和朝廷达成了默契。 | D29: 经验智慧+1、源石技艺适应性+3、精神意志+1、教育+4、源石技艺理论+1 特质【高贵】消耗的社交点×50%、【元素耐受】消耗的特质点-5 使用电能源石技艺进行相关检定时，获得两个奖励骰。 | E29: 萨尔贡的慷慨. 王酋 | F29: 0 | G29: 附加限制：角色在创建完毕后的经济评级不可低于40 描述：你是萨尔贡帝国中的一名王酋，虽然因帝国混乱的基层行政系统，王酋们的控制力与管理范围都各不相同，但你依然拥有着为帝国统合并管理当地社群的职责。 | H29: 教育-2、经济评级+5 获得附加技能：萨尔贡语，初始技能值为10 与显贵人物进行交涉时，交涉类技能检定的检定骰面升级，与劳苦大众进行交涉时，改为检定骰面降级。
... A34: 萨卡兹（恶魔） | B34: -20 | C34: 萨卡兹是较为少见的泰拉种族，长相各异的萨卡兹在人类的历史中始终遭受着其他种族的敌视。 萨卡兹有着名为“十王庭”的十支重要氏族，根据某些萨卡兹的说法，这十支氏族是近代以来卡兹戴尔的基石。千余年来的动荡生活让萨卡兹不再团结，十王庭也接近分崩离析。大部分人认知中的萨卡兹氏族都是王庭氏族，但也有类似于歌利亚、阿纳萨和鬼等少量非王庭氏族存在。绝大多数萨卡兹都是各氏族的混血。 纵观历史，大多数时间内萨卡兹都保持着四处迁徙的流浪生活，而大部分萨卡兹也很少向外人介绍自己的文化。在这种情况下，很多带有萨卡兹烙印的传统都悄无声息地消失了。现代人熟悉的萨卡兹雇佣兵其实也受到了族群长期流浪的影响。 萨卡兹极易感染矿石病，许多学者相信这与萨卡兹天生的高源石技艺适应性有关，也有人认为这与萨卡兹内部依靠血脉传承的源石技艺有关。萨卡兹间口口相传的传说则将他们的先祖提卡兹摆在神民和先民的对立面，并将矿石病视为敌人对自己施加的疾病和诅咒。 | D34: 生理耐受+2、物理强度+2、源石技艺适应性+3、威吓+4 初始感染值+2d10 个人魅力-3、教育-2、技术-2、交涉-4 与特质【易感】绑定 特质【坚韧体魄】、【体能充沛】、【快速愈合】消耗的特质点-5 | E34: 叙拉古的缄默. 家族秩序 | F34: 20 | G34: 附加限制：/ 描述：你是某个大家族中的一份子，从家族中得到了培养与扶持，并且需要承担起你应行的责任。 | H34: 教育+2、经济评级+5、社交点数+10 获得附加技能：叙拉古语，初始技能值为10
A35: 自定义种族 | E35: 谢拉格的冷冽 | F35: -10 | G35: 你出身于群山环绕之间，受耶拉岗德庇护的雪域之国——谢拉格。位于高原雪山之上的谢拉格虽然气候恶劣，但耶拉岗德的庇护使得谢拉格的居民不再需要为突发的天灾所烦忧。在数百年的时光里，谢拉格与世隔绝，并未产生任何的变革与发展，直到这片土地上规模最大的三个家族选择联合，新生的三族议会在蔓珠院——信奉耶拉岗德的宗教机关——的指引下，迈出了向外界沟通的第一步。如今的谢拉格虽还未能完全与现代的社会接轨，但它也从不会阻拦自己的子民走出这片大山。 | H35: 教育-2、经济评级-5 与特质【耐寒】绑定 获得附加技能：谢拉格语，初始技能值为10
E36: 谢拉格的冷冽. 圣山信仰 | F36: 0 | G36: 附加限制：/ 描述：你对耶拉岗德抱有崇高的信仰，不论你是否在蔓珠院中工作。这份信仰坚定了你的意志，并一定程度上使你得到了耶拉岗德的庇护。 | H36: 教育-2、经济评级-5、精神意志+1 与特质【耐寒】绑定 获得附加技能：谢拉格语，初始技能值为10 特质【崇高信念】、【视死如归】消耗的特质点×50%
A37: 已选特质消耗 | B37: =IFERROR(VLOOKUP(主卡!L14,A3:B35,2,0),"") | E37: 伊比利亚的余晖 | F37: -10 | G37: 你出身于广袤海洋的征服者与罹难者——伊比利亚。这个伟大的国家曾是这片大地无可争议的开拓者，但现在，一切都随着海嗣的歌声陷入静谧，废墟中只有属于审判庭手中提灯的微弱火光尚在跳动。 | H37: 教育-3、经济评级-5 获得附加技能：伊比利亚语，初始技能值为10
E38: 伊比利亚的余晖.审判庭之手 | F38: 20 | G38: 附加限制：/ 描述：你成为了审判庭中的一员。你从审判庭内部的卷宗中了解到了“恐鱼”不为人所知的一面，并且将它们最初的名字——“海嗣”视作自身永恒的仇敌，势要将它们驱逐出伊比利亚的海岸线。 | H38: 教育-3、经济评级-5、刀剑+1、源石技艺理论+1、先史+3 获得附加技能：伊比利亚语，初始技能值为10 与修正因子【猎杀者（深海）】绑定
E39: 拉特兰的圣洁 | F39: 30 | G39: 你出身于无数人心中的圣地，这片大地的奇迹之城——拉特兰。这座洁白而神圣的城市是萨科塔的聚集地，但其中也不乏异族往来。拉特兰居民的权利与机遇从未因种族而产生差异，而它的教育普及程度与医疗资源更是令这片大地的所有国家都望尘莫及。对于其他国家的人民而言，拉特兰教与拉特兰甜品是这个国家最广为人知的特点，或许不是每个萨科塔都能熟背繁琐的经文，但每个萨科塔都必定拥有品鉴甜品的能力——并有极大可能拥有制作甜品的厨艺。 | H39: 教育+4、经济评级+10、社交点数+10 特质【互助信条】、【铳械专家】消耗的特质点×50% 获得附加技能：拉特兰语，初始技能值为10
E40: 拉特兰的圣洁. 戍卫羽翼 | F40: 30 | G40: 附加限制：角色种族不为萨科塔时；该修正因子强制选择 描述：你与萨科塔一般热爱这个国家，愿意为其付出一切，但你并非“天使”们的一员。即使圣城包容且乐于接纳任何人，仍有一些东西是他族难以享受，甚至难以感知的。 | H40: 教育+4、经济评级+10 特质【互助信条】、【铳械专家】消耗的特质点×50% 获得附加技能：拉特兰语，初始技能值为10
E41: 卡兹戴尔的苦难 | F41: -20 | G41: 你出身于无数次倒塌而又被再度重建的，独属于萨卡兹的家园——卡兹戴尔。如今的卡兹戴尔在双王的指引下逐渐补齐了基础设施，成为了真正能够安居的家园。即使它与这片大地其他强盛的国家仍有差距，但萨卡兹并不会，更没有资格奢求更多。 | H41: 源石学+2 经验智慧-2、教育-4、经济评级-10 获得附加技能：萨卡兹语，初始技能值为10
E42: 卡兹戴尔的苦难.动荡年代 | F42: -15 | G42: 附加限制：/ 描述：你在卡兹戴尔的移动板块上生活了许久，并习惯了它无休止的碰撞。即使是在更为复杂的环境中，你也能保持专注与镇定。 | H42: 灵巧+2、镇定+2、源石学+2、经验智慧-2、教育-4、经济评级-10 获得附加技能：萨卡兹语，初始技能值为10
E43: 萨米的护佑 | F43: -20 | G43: 你出身于极北之地的无尽冻土——萨米。虽然这片土地与外界封闭许久，但萨米之灵永远庇护祂的每一位子民。每一个部落都已准备好为萨米奉献一切，为此他们世代与邪魔抗争，誓要使其无法踏入萨米半步。 | H43: 教育-2、技术-2、经济评级-10 与特质【耐寒】绑定 获得附加技能：萨米语，初始技能值为10
E44: 萨米的护佑. “军团” | F44: 20 | G44: 附加限制：角色在创建完毕后的精神意志不低于8 描述：萨米人为抗击北方邪魔的侵扰而组建了一支军团——“索阿特维亚卡”，这支庞大的队伍由萨米最勇猛的部落中最强大的战士组成，你正是其中的一员。 | H44: 教育-2、技术-2、经济评级-10、精神意志+1、生理耐受+1、物理强度+1、反应机动+1 获得附加技能：萨米语，初始技能值为10 与特质【先史通晓者】【耐寒】绑定 与修正因子【猎杀者（坍缩体）】绑定
...

Sheet 次要特质表
A1: 序号 | B1: 特质类型 | C1: 特质名称 | D1: 特质描述 | E1: 特质效果 | F1: 点数花费
A2: 1 | B2: 躯体天赋 | C2: 年幼 | D2: 你的角色的年龄对于你的种族的平均寿命，以及你所处社会环境的教育阶段来说处在较早的时期，即你的角色处于通常意义上的“未成年人”阶段，因而对您的角色产生了一系列规则上的影响。 并非所有年龄较小的角色都需要选取本特质。下文所提及的各种效果，同时也是用于判断您是否具有该特质的条件。只要您觉得您的角色足够早熟，并且其人生经历足以说服SN，就可不选取本特质。 | E2: 当角色成长到足够脱离“幼年”时，便可以去除该特质。 身高、体重标准值-20%～50% 你可以（并且通常来讲必须）获得一个任意人脉，该人脉对应的角色被视作你的监护人。你的经济评级会被视为与其相同，并且你可能被允许使用其拥有的头衔与人脉。一般而言，该人脉不需要消耗社交点数，但若该人脉足够特殊/你希望它更为特殊，就应当花费额外的社交点数以提升其价值。 在文明程度足够高的地区，你的角色会被归为“未成年人”，并适用一系列相关的规则，例如民事能力受限、受到特定法律的保护，被要求履行受教育的义务、只需购买半价门票等。 | F2: 0
A3: 2 | B3: 躯体天赋 | C3: 未来可期 | D3: 你的躯体尚未发育完全，并且你确信你的能力还能提升到更高的阶段。 | E3: 生理耐受-1、物理强度-1 失去特质【年幼】时，保留该修正因子提供的特质点。 | F3: -10
A4: 3 | B4: 躯体天赋 | C4: 特殊视野 | D4: 你因先天的种族优势或是后天的变异与改造而获得了特殊的视野，以使得自身能够脱离可见光的限制，在更为恶劣或是更为特殊的环境中得以视物。 | E4: 与至少一个该特质的修正因子绑定。 | F4: 0
A5: 4 | B5: 躯体天赋 | C5: 特殊视野（红外） | D5: 你能够通过红外视觉穿透障碍物并观察到拥有温度的物体——包括绝大部分常见的生物，以及体表并未加装隔热板的机械装置。 | E5: 角色执行【侦测】动作时，检定骰面升级，无视掩体。 | F5: 10
A6: 5 | B6: 躯体天赋 | C6: 特殊视野（黑暗） | D6: 你仅需要极为微弱的光线就能正常视物，也因此对光照条件的要求更低。但在完全无光的环境下，你依然无法获得视野。 | E6: 角色的视野范围不受光照条件限制，且不会因相关环境获得“目盲”。 在光照条件恶劣的环境内依然能够正常行动，不会因此获得减益效果。 | F6: 10
A7: 6 | B7: 躯体天赋 | C7: 感知 | D7: 你因源石技艺或是生物改造而获得了一种独特的感知能力，并且能够以此感应周围的活物。 | E7: 角色使用对应的感知方式执行【侦测】动作时，检定骰面升级，无视掩体。 角色无视“目盲”。 | F7: 20
A8: 7 | B8: 躯体天赋 | C8: 环境感知 | D8: 你的感知能力足够的敏锐与灵活，其不仅能够作用于活物之上，还能代替视觉与触觉以感应周遭环境的形状甚至色彩。 | E8: 角色不会因缺少视野等原因获得负面影响。 | F8: 10
A9: 8 | B9: 躯体天赋 | C9: 物法兼修* | D9: 你的角色顺利地将源石技艺融入到了你的战斗风格中。 | E9: 你的角色总是能学习符合自己精英化阶段的源石技艺，即使你的职业分支并不允许。 | F9: 15
A10: 9 | B10: 躯体天赋 | C10: 长寿 | D10: 你天生便拥有比寻常种族更长的寿命，并且衰老对你的影响也更为微弱。 | E10: 如果你的角色的年龄超过了所处环境大多数人的预期寿命，教育+3。 角色不会因年龄增长而获得特质【年迈】 | F10: 10
A11: 10 | B11: 躯体天赋 | C11: 不老* | D11: 你通过某种方式让自己的躯壳维持在健康的状态下且不再会自然衰老，以此成为了“长生者”——以最为宽泛的标准而言。 | E11: 教育+X。X=角色年龄×5%，至多为5 你不会因年龄增长而受到任何负面影响。 | F11: 10
A12: 11 | B12: 躯体天赋 | C12: 复活* | D12: 角色能够在彻底死亡后，通过某种方式重新归来。这种方式可能是预存的分身，可能是基于某种权能的秘术，可能是提前准备好的源石技艺......复活后，角色将会恢复至自身的最佳状态。需要说明的是，此类复活并不是“原地复活”，而是在远离危险的地方或一段较长的时间之后。如果你的角色在战斗中死亡，那么这个这些使你能够复活的因素至少要在这场战斗结束之后（或者在远离这场战斗的地方）生效。 | E12: 设定某种能使你的角色死而复生的方法。你的角色在死亡后，可以通过这种预设的方法重新归来。 | F12: 30
A13: 12 | B13: 躯体天赋 | C13: 轮回 | D13: 你为存在的延续付出了沉重的代价。在复活后，你失去了过去绝大部分的记忆，以及相应的知识与能力。 | E13: 触发特质效果后，角色等级被重置为1级，并失去所有技能、技艺，拥有的特质需要消耗等额特质点才可重新获得其效果。 | F13: -15
... A91: 90 | B91: 躯体缺陷 | C91: 维护需求 | D91: 角色不具有自我恢复的能力，但能够通过进行某些特定的行动并消耗对应资源以修复自身，例如服用药物，进行祭祀或补充零件。对于一些并非碳基生物的角色来说，这可能是很常见的情况。 | E91: 角色不再受伤残等级影响。 设定一种特定的资源（以及对应的恢复操作），只有消耗此类资源时，你的角色才能进行自我恢复。 在长休时，能够通过消耗价值1源石锭的资源令角色回复20%的生命值上限。 | F91: 10
A92: 91 | B92: 躯体缺陷 | C92: 肢体缺失 | D92: 你的角色缺少某些特定的肢体，这对于你的角色产生了明显不自然的不利影响。 | E92: 这是一个自定义特质，因为它能起到的作用十分繁多，有待补充。例如，尾部的确实可能让角色更加难以保持平衡；角部的缺失可能会降低角色的个人魅力（但更方便隐藏自己的种族特征），手的缺失可能会降低角色的物理强度；以及禁用妙手技能的某些能力；腿部的缺失可能会降低角色的反应机动、移动与负重能力…… 也许规则书未来会完整地规定各种缺失带来的效果，但在当前阶段，就请尽情发挥想象力吧！ | F92: 价值不定
A93: 92 | B93: 躯体缺陷 | C93: 弱点 | D93: 你的角色存在若干个特定的弱点，例如持有某个未痊愈的伤口，缺乏对某种化学物质的抵抗性，在某种环境的条件下状态虚弱等。 | E93: 与你的SN设定一种行之有效的，用于针对你的角色的手段，并且写明这种手段会对你角色带来的负面效果！ | F93: 每个-10
A94: 93 | B94: 精神天赋 | C94: 独行长路 | D94: 你的角色由于个人经历或某些天赋而对独处状态感到从容自若，并且擅长于孤身作战。 | E94: 独自行动且进行除战斗技能外的任意技能检定时，获得骰面升级。 战斗中，若不存在友方角色，则在每个战斗轮结束后获得一个额外回合。 | F94: 20
A95: 94 | B95: 精神天赋 | C95: 孤勇 | D95: 你的角色是一位独狼排斥在战斗中接受来自他人的援助。 | E95: 无法获得来自其他角色的治疗与生命值回复效果。 回合结束时，回复等同于生命值上限*10%的生命值。 | F95: 0
A96: 95 | B96: 精神天赋 | C96: 异格者 | D96: 你的角色掌握了至少两种截然不同的作战之道。尽管它们因武器或防具的不适配而无法同时被运用，但也不妨碍你能够在战斗外灵活地转换自身的战斗定位。 | E96: 你能够选择两种不同的职业分支，用相互独立的技艺点制作两套截然不同的技艺组和战斗信息。同一时间内，只能启用其中一个。 你能够在短休时切换自己的职业分支与所用的防具与武器。切换时，会保持HP与SP与其最大值的比例不变。 | F96: 15
A97: 96 | B97: 精神天赋 | C97: 融会贯通 | D97: 临阵磨枪，不快也光。 | E97: 角色能够进行分支转换。 分支转换：消耗一个主要行动与一个快速行动，转变自己的职业分支。每场战斗首次进行该动作时，触发所有“战斗开始时”效果。 | F97: 15
A98: 97 | B98: 精神天赋 | C98: 武器大师 | D98: 你的角色擅长运用各式各样的武器，并且将他们的用法融会贯通。 | E98: 当你进行任意的战斗技能检定时，可以将其替换为该技能与另一个战斗技能（但不能是通识技能）的协助检定。 | F98: 10
A99: 98 | B99: 精神天赋 | C99: 多重源石技艺* | D99: 你的角色通过某种方法掌握了两种（甚至更多种）截然不同的源石技艺，并且将其融会贯通。 | E99: 你在学习源石技艺时，能够从两种不同小类的源石技艺中选择。两者所花费的技艺点共享，解锁进度相互独立。 | F99: 25
A100: 99 | B100: 精神天赋 | C100: 对立统一 | D100: 你从两种不同的源石技艺类别中找到了它们能力的相似之处，并以此将二者连接为一个统一的体系。 | E100: 你所选取的两种源石技艺小类从属于相同的大类（例如咒法化形、传心感知等），或是两者之间有相互促进的联系（如冰与水，或与风等）。 | F100: -10
A101: 100 | B101: 精神天赋 | C101: 众妙之门 | D101: 你对源石技艺的理解已经远超凡人，因而在你的眼中，所有源石技艺之间的共性压倒了特性。 | E101: 你能够从超过两种，甚至是从所有小类的源石技艺中任意地学习源石技艺。 | F101: 50
A102: 101 | B102: 精神天赋 | C102: 飘忽不定* | D102: 你的角色出于某些原因拥有古怪的运气或诡异的行为模式，因而相比于其他人会存在更不稳定的发挥。 | E102: 角色在进行检定时，您或者您的SN可以要求你外投掷一枚D20，如果出目为1，则本次检定视为大失败；若出目为20，则本次检定视为大成功；若不为1也不为20，则本次检定正常进行。这个效果仅可用于战斗外。 | F102: 0
A103: 102 | B103: 精神天赋 | C103: 追踪专家 | D103: 你的角色尤其擅长追查现场的蛛丝马迹，从中获取线索或直接定位你所追寻的目标。 | E103: 追踪+2 以同一单位为目标进行追踪检定时，每对其进行过一次追踪检定，使追踪+1，持续至下一次长休或是你更改目标。 使用追踪技能与任意单位的潜行技能进行对抗时，获得骰面升级 | F103: 10
A104: 103 | B104: 精神天赋 | C104: 制造专家 | D104: 你的角色在制造各类物品时具有显著优势。无论是武器、防具、工具还是其他特殊道具，他们都能够以更高的效率和更好的质量完成制造。另一方面，你的角色也擅长对工业制成品进行修理，甚至是发明一些全新的机械产物。 | E104: 机械工程+2、电子工程+1 在战斗结束后，可将在战斗中被摧毁的机械单位回收为材料，视重量将其转化为一定的材料单位，且角色至多携带5个单位。在长休时，能够将材料单位变为等量的源石锭。 进行长/短休时，角色可消耗一定资源（如耐力或源石锭）修复未被摧毁的机械单位。 在进行长休时，可以消耗等同于其价格的源石锭来购买（实际上是制作）规则书中的消耗品。 你可以尝试与你的SN讨论设计新的配件。 | F104: 20
A105: 104 | B105: 精神天赋 | C105: 动物共情 | D105: 你的角色不仅能与人类分享的感情，还能与动物这样做！你能够了解与你相处的动物所处的情绪，并且能够借此与动物更好地相处，从而驯化他们，甚至通过动作与对方进行沟通。 | E105: 你总是能够了解与你互动的动物的心情与需求。 你能够通过肢体等动作与动物进行交涉类技能检定，以将其驯服。安抚，或使其了解到你的需求。 | F105: 10
A106: 105 | B106: 精神天赋 | C106: 动物语言 | D106: 你不仅能够与动物进行情感上的交流，更能通过言语沟通以获取实质性的信息。你不再是单纯地使动物了解你的想法，而是能够从一些具有足够智能的动物中获取信息建议，乃至进行深入复杂的沟通。 | E106: 能够与动物进行语言沟通，尽管大部分动物智能有限。 能够了解动物的各种鸣叫和行为的意义。 | F106: 20
A107: 106 | B107: 精神天赋 | C107: 种类限制 | D107: 选取不超过三个物种，该特质仅可对选取物种生效。 | E107: 选取不超过三个物种，该特质仅可对选取物种生效。 | F107: 该特质总消耗-50%
A108: 107 | B108: 精神天赋 | C108: 共情者 | D108: 你的角色有较强的共情能力，这使得你的角色更擅长交际，并且往往能从谈话中获取到其他角色所不了解的信息。当然，这也使得你的艺术创造更能反应人的悲欢喜乐，进而提高了你的艺术水平。 | E108: 交涉类技能+1、情感+3 你总是能从SN的提示中得到与周围其他角色情感相关的提示。你周围的角色因做出了与其性格不符的行动时，你将得知。 你的艺术创作能稳定地唤起欣赏者的某种情感（通常是你希望的）。 如果SN认为某角色此时的行为模式是“情绪化的”，并且你了解了他的具体情绪，则你对其进行交涉类技能检定时，获得骰面升级。 | F108: 15
A109: 108 | B109: 精神天赋 | C109: 猎杀者 | D109: 你的角色尤其擅长猎杀某一类单位，熟悉目标的攻击方式、生活习性、行为意图、战斗习惯等等，而这一切的研究则都是为了更快更好地将之猎杀。你谙于此道，且屡试不爽。 | E109: 在选取这个特质时，需要同时选定某一类单位，例如机械、野兽、感染生物、邪魔、海嗣、甚至是某一种人类（例如萨卡兹或萨科塔，也可以是某个具体的组织群体）。 | F109: 0
A110: 109 | B110: 精神天赋 | C110: 猎杀者（目标） | D110: 你在与这类目标的常年战斗中吸取了足够的经验，以使你确 信自身能够将你遇到的所有目标都杀戮殆尽——而你也的确拥有如此的 能力。 | E110: 选择一个单位标签/种族（或是更为概念化的群体，如某一团体），该单位标签/种族为目标。 与拥有该单位标签/属于该种族的单位——即“目标”——进行对抗时，获得骰面升级。 你能够尝试进行任意合理的技能检定或对抗以寻找“目标”的“弱点”（通常是某些条件或针对行动的限制）。若你的行动能够满足弱点的条件/限制，你的检定可能获得奖励骰/“目标”检定可能获得惩罚骰。若SN并未为此单位设计弱点，可以改为提供一个行为意图。 击倒一个与角色战力相近的敌方“目标”单位时，使自身的生命值回复等同于已损失量的50%。 该修正因子可重复购买，购买该修正因子时，使下次购买该修正因子所需的特质点×2。 | F110: 10
A111: 110 | B111: 精神天赋 | C111: 觉察者 | D111: 你的角色思绪敏锐，明察秋毫，通常在绝大情况下都有所防备，这使其难以被偷袭。 | E111: 觉察+2 你无视突袭轮的负面效果。 若SN允许，你可以使用觉察技能与袭击者的潜行/战斗技能进行对抗以提前发觉袭击，并在对抗成功后使你所属的阵营免受突袭。 | F111: 10
A112: 111 | B112: 精神天赋 | C112: 不可动摇 | D112: 你的角色对自我信念的认知非常清晰，这使得你能够不受其他人的刻意干扰而做出决断。 | E112: 精神意志+1 进行精神意志检定时，获得骰面升级 任意单位试图对你使用交涉类技能进行检定，或是释放了传心感知类的源石技艺时，检定骰面降级。若其检定失败，你将得知此事。 你回合开始时，若具有“恐惧”状态，则可进行一次精神意志检定，若成功，清除之。该检定的难度等级状态的施加者相关。 | F112: 20
A113: 112 | B113: 精神天赋 | C113: 崇高目标 | D113: 你的角色在追求某个特殊的目标时会受到驱策，超越其平时的极限。你的角色必须发自内心地认同这一目标，相信实现这一目标代表了自己生命的最终价值，进而不仅要在这个特质启用时追求这一目标，更要在任何时间都尝试努力去实现之。如果不这样做，不仅该特质会失效，你的角色也可能会因此而积累压力。 目标本身不应当太过宽泛，同时本身也不能太容易完成。“与萨科塔战斗”就太过宽泛，“彻底毁灭拉特兰”则还有可供商椎的空间。SN总是能够定义哪些行为能应用这一特质，而那些行为不能。 | E113: 在进行非攻击检定，且检定内容与实现这一目标直接相关时，检定获得一个奖励骰。 若你完全实现了你的目标，角色等级+1，且可以在本次模组结束后重新选取一个目标。 | F113: 10
A114: 113 | B114: 精神天赋 | C114: 铳械专家 | D114: 你的角色有丰富的铳械使用、维护与改装经验，这使得你的角色能 够行之有效地运用铳械。 | E114: 你的角色使用铳械攻击时，不会触发完全闪避或完全格挡/招架。 | F114: 10
A115: 114 | B115: 精神天赋 | C115: 团队意识 | D115: 你的角色十分擅长团队协作，这使得你的角色更容易与友方角色进行配合来完成任务。 | E115: 在非战斗时，你能够与其他角色共同进行任何工作，从而将这一工作所需的检定转为协作检定，只要其中一个检定成功即算成功。 每场战斗限一次，回合开始时，你可立刻结束回合，并使一名友方单位立刻获得一个额外回合。 在模组结束时，你可以在任意友方角色同意的情况下，获得该角色“相识”或“朋友”的人脉而不消耗社交点数，每个模组至多可因此获得三个“朋友”人脉。 | F115: 20
A116: 115 | B116: 精神天赋 | C116: 视死如归 | D116: 你的角色并不畏惧死亡，而是将死亡视为自己的归宿。一方面，这能让你的角色不会因濒死或面对难以获胜的战斗而发生动摇，但也在一定程度上降低了角色的求生意志。 一般来说，角色需要因具体的原因而视死如归，这需要成为角色的信念，并且贯彻在它的扮演中。如果角色甚至不能让SN认为这个角色有向死的意志，则这个特质则也会被判定为不生效。 | E116: “濒死”时，角色无视“恐惧”、“濒死”状态效果。处于“濒死”时，将受到的折前伤害改为降低等量的生命值上限。 每场战斗限一次，角色获得“濒死”时，清除所有负面状态，元素韧性回复至上限，该战斗轮结束时立刻获得一个额外回合。 | F116: 30
A117: 116 | B117: 精神天赋 | C117: 幸运儿 | D117: 你的角色有着离奇的运气，正是来自幸运的眷顾常常使得你的角色在最危险的时刻化险为夷。 | E117: 每次短休限一次，在你受到任意攻击，且本次攻击造成的伤害将使角色的生命值降低至0时，将本次攻击的伤害变为其最小值。 | F117: 10
...

Sheet 配件及消耗品
A1: 配件名称 | B1: 适用条件 | C1: 配件效果 | D1: 配件价值 | E1: 消耗品 | F1: 消耗效果 | G1: 道具价格
A2: 华丽武器装饰 | B2: 武器 | C2: 向他人展示你的武器时，个人魅力临时+1 | D2: 5 | E2: 丰蹄能量饮料 | F2: 提供主动动作【饮用！】：消耗快速行动与该物品，获得4SP。同类效果每日限一次。 | G2: 3
A3: 隐蔽武器 | B3: 武器 | C3: 你的武器可以通过某种方式收纳隐藏起来。为隐藏武器而进行乔装或欺诈检定时骰面升级。 | D3: 5 | E3: 医疗喷雾 | F3: 提供主动动作【护理】：消耗快速行动与该物品，为自身恢复50%的已损失生命值 | G3: 3
A4: 猎杀改装 | B4: 武器 | C4: 选择一类目标（如野兽、机械等），武器攻击此类目标时，造成的伤害+3 | D4: 5 | E4: 紧急活性针剂 | F4: 提供主动动作【注射！】：消耗快速行动与该物品，获得8SP。同类效果每日限一次。 | G4: 6
A5: D32钢施术改装 | B5: 武器并非施法媒介 | C5: 使得该武器可以被视为施法媒介。施法范围默认为中坚术士范围。 | D5: 5 | E5: 急救包 | F5: 进行急救时，消耗该物品以直接提前结束【引导】。 | G5: 2
A6: 双极纳米片改装 | B6: 武器并非施法媒介 | C6: 使得该武器可以被视为施法媒介。施法范围默认为中坚术士范围。 允许你释放一个符合你精英化阶段的源石技艺，即使你并未习得该技艺。每场战斗限一次 | D6: 10 | E6: 绷带 | F6: 提供主动动作【止血】：若组织损伤爆发，可消耗快速行动与该物品，结束组织损伤爆发，并恢复X点HP。X=角色总等级 | G6: 1
A7: 精钢强化 | B7: 近战武器 | C7: 武器攻击造成的物理伤害+1点。 | D7: 10 | E7: 烫伤膏 | F7: 提供主动动作【敷药】：若灼燃损伤爆发，可消耗快速行动与该物品，结束灼燃损伤爆发，并恢复X点HP。X=角色总等级 | G7: 1
A8: 异铁锐化 | B8: 近战武器 | C8: 每回合首次武器攻击造成的物理伤害+3点。 | D8: 10 | E8: 解毒药 | F8: 提供主动动作【解毒】：若毒性损伤爆发，可消耗快速行动与该物品，结束毒性损伤爆发，并恢复X点HP。X=角色总等级 | G8: 1
A9: 射弹机构 | B9: 近战武器 | C9: 提供主动动作【射弹】：消耗快速行动，对前方五个战术格内最近一战术格内的某单位进行一次远程物理攻击，这次攻击被视为使用射击技能的重射手武器攻击。每场战斗限一次 | D9: 5 | E9: 干燥粉 | F9: 提供主动动作【干燥】：若侵蚀损伤爆发，可消耗快速行动与该物品，结束侵蚀损伤爆发，并恢复X点HP。X=角色总等级 | G9: 1
A10: 放血槽 | B10: 近战锐器 | C10: 每回合攻击首次命中并造成伤害时，每有一颗骰子骰出了最大值或最小值，就额外造成1点组织损伤。 | D10: 10 | E10: 清洁湿巾 | F10: 提供主动动作【明目】：若角色【目盲】，可消耗快速行动与该物品，清除之。 | G10: 1
A11: 延伸模块 | B11: 非长兵武器 | C11: 攻击范围向正前方延伸一格。攻击时，需要同时进行原武器的攻击检定和长兵检定，检定结果取两者之中较低者。 | D11: 10 | E11: 工程炸药 | F11: 提供主动动作【工程爆破】：消耗主要行动，选择前方一格的战术格，摧毁其中的工业或民用级障碍地形，或者对其中的地形单位造成100点物理伤害。 | G11: 3
A12: 工程破拆改装 | B12: 钝器 | C12: 该武器对地形单位造成的伤害+10点。 提供主动动作【破拆】：消耗快速行动，摧毁正前方战术格内的民用级地形障碍。 | D12: 5 | E12: 投掷物 | F12: 投掷效果 | G12: 道具价格
A13: 护盾部署装置 | B13: 盾术武器 | C13: 提供主动动作【部署】：消耗快速行动，从背包中移除该武器，在前方一格内部署地形单位“机动盾牌”。每场战斗限一次。 “机动盾牌”：进行一次盾术检定，其检定结果为该单位的生命值，无抗性。被视为掩体。被摧毁时，将武器添加回背包中。 | D13: 10 | E13: 闪光弹 | F13: 对中心36（距离3）范围内所有不背对该道具所在战术格的单位施加【目盲】，持续至其下个回合结束。 | G13: 3
A14: 闪光护盾 | B14: 盾术武器 | C14: 提供主动动作【闪光】：消耗快速行动，对前方散射手范围内 所有与自己朝向相反的单位施加【目盲】，持续至其下个回合结束， 每场战斗限一次。 | D14: 5 | E14: 烟雾弹 | F14: 在中心12（阶梯2）范围内的所有非障碍战术格中生成地形“烟雾”。 “烟雾”：可通行，不透明，非障碍的地形。战斗轮开始两次后被移除。 | G14: 2
A15: 鞘 | B15: 刀剑武器 | C15: 提供主动动作【纳刀】：消耗主要行动，进入【纳刀】状态。战斗开始时，获得【纳刀】。 【纳刀】：攻击检定时，骰面升级。持续至攻击一次。 | D15: 5 | E15: 燃烧瓶 | F15: 在中心12（阶梯2）范围内的所有非障碍战术格中生成地形“火焰”。 “火焰”：可通行，透明，非障碍的地形。经过该战术格的单位受到2点灼燃损伤，在其中结束回合的单位受到4点灼燃损伤。战斗轮开始两次后被移除。 | G15: 2
A16: 链锯切割引擎 | B16: 兵械操作武器 | C16: 每回合首次攻击命中并造成伤害时，额外造成3点组织损伤。 每场战斗开始前，消耗价值1源石锭的能源为你的武器供能以激活该效果。 | D16: 10 | E16: 高爆手雷 | F16: 对中心8（距离1）范围内的所有单位造成10点物理伤害，摧毁其中的民用障碍。每进入一个新的精英化阶段，伤害就+10点。 | G16: 3
A17: 结构优化 | B17: 远程物理武器 | C17: 武器攻击造成的物理伤害+1点。 | D17: 10 | E17: 破片手雷 | F17: 对中心8（距离1）范围内的所有单位造成5点物理伤害与3点组织损伤。每进入新的一个新的精英化阶段，组织损伤就+2点。 | G17: 3
A18: 优质弹药 | B18: 远程物理武器 | C18: 每回合首次武器攻击造成的物理伤害+3点。 | D18: 10 | E18: 支援气罐 | F18: 对中心8（距离1）范围内的所有单位造成【推击3】。 | G18: 5
A19: 蓝屏脉冲 | B19: 远程物理武器 | C19: 攻击命中并对机械单位（如无人机）造成伤害时，施加【停顿】 | D19: 8 | E19: 干冰炸弹 | F19: 对中心8（距离1）范围内的所有单位施加【寒冷】，持续至下个回合结束。 | G19: 1
A20: 瞄准镜 | B20: 远程物理武器 | C20: 每回合首次攻击命中被瞄准的目标时，造成的伤害+5点。瞄准时，能见度上升一个等级。 | D20: 10 | E20: 震撼弹 | F20: 对中心8（距离1）范围内的所有单位施加【标记】，持续至下个回合结束。 | G20: 2
A21: 夜视镜 | B21: 远程物理武器 | C21: 瞄准时，能见度上升一个等级，且不会因缺少光照而导致能见度下降。 | D21: 3 | E21: 电磁脉冲 | F21: 对中心20（距离2）范围内的所有机械单位施加【眩晕】，持续至下个回合结束。 | G21: 3
A22: 涂毒 | B22: 弩箭或暗器武器 | C22: 攻击命中并造成伤害时，额外造成3点毒性损伤。每次触发该效果时，消耗1源石锭。 | D22: 0
A23: 临时握把 | B23: 暗器武器 | C23: 可通过【切换武器】，将武器转变为造成物理伤害的近战武器。该武器可被视为依赖短兵技能的处决者武器。 | D23: 1
A24: 下挂刺刀 | B24: 射击武器 | C24: 可通过【切换武器】，将武器转变为造成物理伤害的近战武器。该武器可被视为依赖长兵技能的冲锋手武器。 | D24: 1
A25: 激光准直 | B25: 射击武器 | C25: 攻击你正前方的目标时，造成的伤害+5点。 | D25: 10
A26: 投射装置 | B26: 射击武器 | C26: 你可以将【投掷物品】的可用范围替换为你的武器攻击范围。 | D26: 5
A27: 架设模式 | B27: 射击武器 | C27: 提供主动动作【架设】：消耗快速行动，将该武器从背包中移除，在自身所在战术格生成地形单位“射击点”。 “射击点”：具有1生命值，所在战术格内有单位时无法被攻击。角色处在该战术格内时，视为持有某把骰面更高一级的射击武器，且能释放【收回】。被摧毁时，将该武器的故障版本收回背包，在本场战斗中无法再作为武器使用。 【收回】：消耗快速行动，将射击点撤除，其对应的射击武器收回背包。 | D27: 15
A28: 单发再装填组件 | B28: 铳械 | C28: 具有4点弹容量上限，弹容量大于0时才能攻击。攻击时，消耗1弹容量并获得1移动位。 | D28: 3
C29: 提供主动动作【再装填】：消耗快速行动，将弹容量补充到上限。
A30: 连发再装填组件 | B30: 铳械 | C30: 具有6点弹容量上限，弹容量大于0时才能攻击。攻击时，消耗1弹容量并获得1移动位。 | D30: 3
C31: 提供主动动作【再装填】：消耗主要行动，将弹容量补充到上限。
A32: 扩容弹匣 | B32: 具有弹容量的武器 | C32: 弹容量上限+50% | D32: 10
A33: 法杖加固设计 | B33: 施法媒介 | C33: 可通过【切换武器】，将武器转变为造成物理伤害的近战武器。该武器可被视为依赖钝器技能的尖兵武器。 | D33: 1
A34: 法术储存单元I/II/III | B34: 施法媒介 | C34: 选择一种至多为精英化阶段0/0/1的源石技艺，将其储存在施术单元内，至多储存1/2/2次。 你能在战斗中释放该技艺（SP和行动正常消耗），随后将其消耗。在每次长休时，若符合条件，你可以补充已消耗的源石技艺。 | D34: 10/15/20
A35: 法杖扩展单元 | B35: 施法媒介 | C35: 将中坚术士的攻击范围与该武器当前的攻击范围相加（求并集）以作为该武器的新攻击范围。 | D35: 20
A36: 术法分析单元 | B36: 施法媒介 | C36: 你可以立即勘察出至多5立方米范围内的源石技艺反应或残留，并知晓源石技艺类型，该单元在释放一次后失效，长休后恢复。 | D36: 10
A37: 浮游环绕单元 | B37: 施法媒介 | C37: 你的施术单元不需要握在手中依然可以运行，这通常表现为环绕或漂浮在你周围。你的施术单元不再拥有重量负担。 | D37: 3
A38: 术能发射器 | B38: 施法媒介 | C38: 你的施术单元武器可以使用【瞄准】。攻击检定时，分别检定施术与射击，取较低值作为检定结果。 | D38: 15
A39: 夜视头盔 | B39: 防具 | C39: 你的角色不会因缺少光照而导致能见度下降。 | D39: 3
A40: 隐蔽防具 | B40: 防具 | C40: 你将防具隐藏在了常规服饰之下。 | D40: 5
...

Sheet 感染系统
A1: 部位 | B1: 固化症状 | C1: 症状描述 | D1: 症状修正 | E1: 临时发作 | F1: 发作效果
A2: 头部 | B2: 嗜睡症 | C2: 受源石影响，角色将表现出难以克制的困倦欲睡与不非预期的日间入睡现象。在未能缓解睡意的情况下，角色可能会忽视周遭危险环境直接猝倒。 | D2: ·精神意志-1 ·获得“困顿”时，改为获得“睡眠” ·你处于“睡眠”状态并结束回合时，使自身SP恢复至初始值。 ·获得【嗜睡】特质 | E2: 猝倒 | F2: 获得“睡眠”。 | H2: 嗜睡症 | I2: 猝倒
B3: 认知障碍 | C3: 受到源石的影响，角色的行为模式或者语言风格会发生不可控的转变，进而导致对自我认知的分裂或行为模式的失控。典型的症状包括人格分裂，或是听到其他不属于自己的声音等。 | D3: ·精神意志-2。 ·无法成长交涉相关技能 ·获得【精神分裂】特质 | E3: 精神崩溃 | F3: 获得“眩晕”。下一个回合结束时，切换到另一个人格（若有）。 | H3: 认知障碍 | I3: 精神崩溃
B4: 感官失灵 | C4: 源石损害了角色的感官生理功能，诸如眼，鼻、耳、咽喉等。在病情严重的情况下，角色的多个器官都可能受影响而失去功能。该症状的表现形式多样，在症状较轻时也可能表现为幻视、幻听、耳鸣等。 | D4: ·反应机动-2，进行反应机动与洞察相关检定时获得一个惩罚骰 ·精神意志+1，进行精神意志检定时获得一个奖励骰 | E4: 感知紊乱 | F4: 下一次进行攻击时，随机指定目标。 | H4: 感官失灵 | I4: 感知紊乱
B5: 神经衰弱 | C5: 受源石对神经中枢的持续性刺激，角色表现出精神活力下降，工作效率下降，体力不足且需要频繁休息等症状，同时可能出现怕光、怕吵等心理性症状，且在入睡前和夜间症状加重，影响正常睡眠。 | D5: ·精神意志-1，反应机动-1，进行精神意志检定时获得一个惩罚骰 ·拥有“睡眠”状态抵抗 ·长/短休时回复的SP-50% | E5: 思维僵化 | F5: 获得“沉默”、元素韧性降低至1并受到1点凋亡损伤。 | H5: 神经衰弱 | I5: 思维僵化
A6: 躯干 | B6: 肌肉僵化 | C6: 源石侵蚀了角色的肌体，角色在进行剧烈运动时难以施力，在持续性运动时更难维持动作稳定性，甚至可能因大幅度动作引起肌肉僵死而对自身造成伤害。 | D6: ·生理耐受-1，物理强度-1 ·每次长休限一次，消耗耐力时，可改为消耗Xd4生命值。X=角色等级/2 | E6: 组织僵死 | F6: 被视为拥有“脆弱X”，持续至自身的下一个回合结束。X=角色等级。 | H6: 肌肉僵化 | I6: 组织僵死
B7: 躯壳结晶 | C7: 源石在角色的体表凝结出一层壳体，令角色的动作受到影响。这层外壳令角色的抗击打能力更强，但同时也使得体表伤口的自愈速度大大减慢，需要更长的时间来弥合。 | D7: ·个人魅力-2，反应机动-1 ·被视为拥有“庇护” ·生命值上限-20%，长/短休时回复的生命值-50% | E7: 脆性晶体 | F7: 使自身的基础物理抗性与基础法术抗性降低为50%，持续至自身的下个回合结束。 | H7: 结晶躯壳 | I7: 脆性晶体
